Workbook
Name Slicer_____PARETO_SKU_2025: #N/A
Name Slicer_____PARETO_SKU_FEB_2026: #N/A
Name Slicer_____PARETO_SKU_JAN_2026: #N/A
Name Slicer_AVG_FY_24: #N/A
Name Slicer_AVG_FY_25: #N/A
Name Slicer_CUST_GROUP: #N/A
Name Slicer_CUSTNAME_DIST: #N/A
Name Slicer_CUSTNO_DIST: #N/A
Name Slicer_FY_25_VS_FY_24: #N/A
Name Slicer_GROWTH__BY_GROUP_FEB_26: #N/A
Name Slicer_GROWTH__BY_GROUP_JAN_26: #N/A
Name Slicer_GROWTH_FEB_26: #N/A
Name Slicer_GROWTH_FY_25_BY_GROUP: #N/A
Name Slicer_GROWTH_JAN_26: #N/A
Name Slicer_PARETO_SKU_2025: #N/A
Name Slicer_PARETO_SKU_FEB_2026: #N/A
Name Slicer_PARETO_SKU_JAN_2026: #N/A
Name Slicer_RANK_2024: #N/A
Name Slicer_RANK_2025: #N/A
Name Slicer_RANK_2026: #N/A
Name Slicer_TOTAL_FY_2025: #N/A

Sheet DASHBOARD_BR
BI3: RANK 2026 | BJ3: AVG JAN - FEB 2026 | BK3: BUSINESS CONTRIBUTION | BL3: CUSTOMER GROUP NAME | BM3: RANK 2025 | BN3: RANK 2024 | BO3: GROWTH 2025 VS 2024
BI4: 1 | BJ4: 2.7589088e+08 | BK4: 0.20235051 | BL4: KL-TOP 100 | BM4: 1 | BN4: 1 | BO4: 0.20819267
BI5: 2 | BJ5: 1.6451369e+08 | BK5: 0.18687585 | BL5: KA-INDOGROSIR | BM5: 2 | BN5: 2 | BO5: 0.36424418
BI6: 3 | BJ6: 1.5693349e+08 | BK6: 0.14706044 | BL6: KA-ALFAMART | BM6: 3 | BN6: 3 | BO6: 0.12395796
BI7: 4 | BJ7: 1.0158939e+08 | BK7: 0.10859673 | BL7: KL-VICTORIA | BM7: 4 | BN7: 4 | BO7: 0.14615526
BI8: 7 | BJ8: 76259232 | BK8: 0.081049446 | BL8: KL-GOGO | BM8: 5 | BN8: 5 | BO8: 0.31105347
BI9: 5 | BJ9: 85808280 | BK9: 0.055582796 | BL9: KL-JODOH | BM9: 6 | BN9: 6 | BO9: 0.049144122
BI10: 6 | BJ10: 83359604 | BK10: 0.049481329 | BL10: KL-STAR | BM10: 7 | BN10: 8 | BO10: 0.12954458
BI11: 8 | BJ11: 56037630 | BK11: 0.045949262 | BL11: KL-INDAH | BM11: 8 | BN11: 7 | BO11: 0.03542864
BI12: 10 | BJ12: 30317484 | BK12: 0.029951481 | BL12: KL-GROS | BM12: 9 | BN12: 9 | BO12: 0.35823922
BI13: 11 | BJ13: 24784367 | BK13: 0.024058226 | BL13: KA-DIAMOND | BM13: 10 | BN13: 10 | BO13: 0.19230579
BI14: 9 | BJ14: 32263140 | BK14: 0.017646573 | BL14: KL-HALIMAH | BM14: 11 | BN14: 11 | BO14: 0.24817061
BI15: 12 | BJ15: 17408829 | BK15: 0.013256721 | BL15: KL-LOVE | BM15: 12 | BN15: 12 | BO15: 0.21189024
... BI22: 18 | BJ22: 735135.24 | BK22: 0.00024098768 | BL22: KA-INDOMARET | BM22: 19 | BN22: 19 | BO22: 1

Sheet SUMMARY MT 2026
C1: BY OUTLET NAME
J2: GROWTH
B3: CUST-GROUP | C3: RANK 2026 | D3: CUSTNAME_DIST | E3: CUSTNO_DIST | F3: TOTAL FY 2025 | G3: AVG FY 25 | H3: RANK 2025 | I3: AVG FY 24 | J3: RANK 2024 | K3: FY 25 VS FY 24 | L3: GROWTH FY 25 BY GROUP | M3: GROWTH JAN 26 | N3: GROWTH BY GROUP JAN 26 | O3: GROWTH FEB 26 | P3: GROWTH BY GROUP FEB 26 | Q3: GROWTH MAR 26 | R3: GROWTH BY GROUP MAR 26 | S3: GROWTH APR 26 | T3: GROWTH BY GROUP APR 26 | U3: GROWTH MAY 26 | V3: GROWTH BY GROUP MAY 26 | W3: GROWTH JUN 26 | X3: GROWTH BY GROUP JUN 26 | Y3: GROWTH JUL 26 | Z3: GROWTH BY GROUP JUL 26 | AA3: GROWTH AUG 26 | AB3: GROWTH BY GROUP AUG 26 | AC3: GROWTH SEP 26 | AD3: GROWTH BY GROUP SEP 26 | AE3: GROWTH OCT 26 | AF3: GROWTH BY GROUP OCT 26 | AG3: GROWTH NOV 26 | AH3: GROWTH BY GROUP NOV 26 | AI3: GROWTH DEC 26 | AJ3: GROWTH BY GROUP DEC 26 | AK3: PARETO SKU 2025 | AL3: (-) PARETO SKU 2025 | AM3: PARETO SKU JAN 2026 | AN3: (-) PARETO SKU JAN 2026 | AO3: PARETO SKU FEB 2026 | AP3: (-) PARETO SKU FEB 2026 | AQ3: PARETO SKU MAR 2026 | AR3: (-) PARETO SKU MAR 2026 | AS3: PARETO SKU APR 2026 | AT3: (-) PARETO SKU APR 2026 | AU3: PARETO SKU MAY 2026 | AV3: (-) PARETO SKU MAY 2026 | AW3: PARETO SKU JUN 2026 | AX3: (-) PARETO SKU JUN 2026 | AY3: PARETO SKU JUL 2026 | AZ3: (-) PARETO SKU JUL 2026 | BA3: PARETO SKU AUG 2026 | BB3: (-) PARETO SKU AUG 2026 | BC3: PARETO SKU SEP 2026 | BD3: (-) PARETO SKU SEP 2026 | BE3: PARETO SKU OCT 2026 | BF3: (-) PARETO SKU OCT 2026 | BG3: PARETO SKU NOV 2026 | BH3: (-) PARETO SKU NOV 2026 | BI3: PARETO SKU DEC 2026 | BJ3: (-) PARETO SKU DEC 2026
B4: KA-INDOGROSIR | C4: =RANK(IFERROR(VLOOKUP(Table2[[#This Row],[CUSTNO_DIST]],STM!B:C,2,FALSE),0),STM!$C$5:$C$65,0) -> 1 | D4: PT.INTI CAKRAWALA CITRA | E4: MTA00101-10100021 | F4: 3.2192001e+09 | G4: 2.6826667e+08 | H4: =RANK(G4,$G$4:$G$64,0) -> 1 | I4: 1.9664124e+08 | J4: =RANK(I4,$I$4:$I$64,0) -> 1 | K4: =IFERROR(G4/I4-1," ") -> 0.36424418 | L4: =IFERROR(VLOOKUP(Table2[[#This Row],[CUST-GROUP]],$E$70:$K$88,7,FALSE),0) -> 0.36424418 | M4: =IFERROR(VLOOKUP(E4,STM!G:K,4,FALSE),0)/G4-1 -> -0.08181651 | N4: =IFERROR(VLOOKUP('SUMMARY MT 2026'!$B4,$E$70:$M$88,8,FALSE),0) -> -0.08181651 | O4: =IFERROR(VLOOKUP(E4,STM!G:K,5,FALSE),0)/G4-1 -> -0.69168978 | P4: =IFERROR(VLOOKUP('SUMMARY MT 2026'!$B4,$E$70:$M$88,9,FALSE),0) -> -0.69168978 | AK4: =IFERROR(VLOOKUP(E4,[1]dashboard_SYAIFUL!$E$4:$AZ$76,47,FALSE),0) -> 0 | AL4: =IFERROR(VLOOKUP(E4,[1]dashboard_SYAIFUL!$E$4:$AZ$76,48,FALSE),0) -> 0 | AM4: =IFERROR(VLOOKUP(E4,[1]dashboard_SYAIFUL!$E$4:$BD$76,49,FALSE),0) -> 0 | AN4: =IFERROR(VLOOKUP(E4,[1]dashboard_SYAIFUL!$E$4:$BD$76,50,FALSE),0) -> 0 | AO4: =IFERROR(VLOOKUP('SUMMARY MT 2026'!$E4,[1]dashboard_SYAIFUL!$E$4:$CP$76,89,FALSE),0) -> 0 | AP4: =IFERROR(VLOOKUP('SUMMARY MT 2026'!$E4,[1]dashboard_SYAIFUL!$E$4:$CP$76,90,FALSE),0) -> 0 | AR4: =35-Table2[[#This Row],[PARETO SKU MAR 2026]] -> 35 | AT4: =35-Table2[[#This Row],[PARETO SKU MAR 2026]] -> 35 | AV4: =35-Table2[[#This Row],[PARETO SKU MAR 2026]] -> 35 | AX4: =35-Table2[[#This Row],[PARETO SKU MAR 2026]] -> 35 | AZ4: =35-Table2[[#This Row],[PARETO SKU MAR 2026]] -> 35 | BB4: =35-Table2[[#This Row],[PARETO SKU MAR 2026]] -> 35 | BD4: =35-Table2[[#This Row],[PARETO SKU MAR 2026]] -> 35 | BF4: =35-Table2[[#This Row],[PARETO SKU MAR 2026]] -> 35 | BH4: =35-Table2[[#This Row],[PARETO SKU MAR 2026]] -> 35 | BJ4: =35-Table2[[#This Row],[PARETO SKU MAR 2026]] -> 35
B5: KA-ALFAMART | C5: =RANK(IFERROR(VLOOKUP(Table2[[#This Row],[CUSTNO_DIST]],STM!B:C,2,FALSE),0),STM!$C$5:$C$65,0) -> 2 | D5: PT.SUMBER ALFARIA TRIJAYA | E5: MTA00101-10100050 | F5: 2.5333233e+09 | G5: 2.1111028e+08 | H5: =RANK(G5,$G$4:$G$64,0) -> 2 | I5: 1.8782756e+08 | J5: =RANK(I5,$I$4:$I$64,0) -> 2 | K5: =IFERROR(G5/I5-1," ") -> 0.12395796 | L5: =IFERROR(VLOOKUP(Table2[[#This Row],[CUST-GROUP]],$E$70:$K$88,7,FALSE),0) -> 0.12395796 | M5: =IFERROR(VLOOKUP(E5,STM!G:K,4,FALSE),0)/G5-1 -> 0.35969226 | N5: =IFERROR(VLOOKUP('SUMMARY MT 2026'!$B5,$E$70:$M$88,8,FALSE),0) -> 0.35969226 | O5: =IFERROR(VLOOKUP(E5,STM!G:K,5,FALSE),0)/G5-1 -> -0.87294807 | P5: =IFERROR(VLOOKUP('SUMMARY MT 2026'!$B5,$E$70:$M$88,9,FALSE),0) -> -0.87294807 | AK5: =IFERROR(VLOOKUP(E5,[1]dashboard_SYAIFUL!$E$4:$AZ$76,47,FALSE),0) -> 0 | AL5: =IFERROR(VLOOKUP(E5,[1]dashboard_SYAIFUL!$E$4:$AZ$76,48,FALSE),0) -> 0 | AM5: =IFERROR(VLOOKUP(E5,[1]dashboard_SYAIFUL!$E$4:$BD$76,49,FALSE),0) -> 0 | AN5: =IFERROR(VLOOKUP(E5,[1]dashboard_SYAIFUL!$E$4:$BD$76,50,FALSE),0) -> 0 | AO5: =IFERROR(VLOOKUP('SUMMARY MT 2026'!$E5,[1]dashboard_SYAIFUL!$E$4:$CP$76,89,FALSE),0) -> 0 | AP5: =IFERROR(VLOOKUP('SUMMARY MT 2026'!$E5,[1]dashboard_SYAIFUL!$E$4:$CP$76,90,FALSE),0) -> 0 | AR5: =35-Table2[[#This Row],[PARETO SKU MAR 2026]] -> 35 | AT5: =35-Table2[[#This Row],[PARETO SKU MAR 2026]] -> 35 | AV5: =35-Table2[[#This Row],[PARETO SKU MAR 2026]] -> 35 | AX5: =35-Table2[[#This Row],[PARETO SKU MAR 2026]] -> 35 | AZ5: =35-Table2[[#This Row],[PARETO SKU MAR 2026]] -> 35 | BB5: =35-Table2[[#This Row],[PARETO SKU MAR 2026]] -> 35 | BD5: =35-Table2[[#This Row],[PARETO SKU MAR 2026]] -> 35 | BF5: =35-Table2[[#This Row],[PARETO SKU MAR 2026]] -> 35 | BH5: =35-Table2[[#This Row],[PARETO SKU MAR 2026]] -> 35 | BJ5: =35-Table2[[#This Row],[PARETO SKU MAR 2026]] -> 35
B6: KL-VICTORIA | C6: =RANK(IFERROR(VLOOKUP(Table2[[#This Row],[CUSTNO_DIST]],STM!B:C,2,FALSE),0),STM!$C$5:$C$65,0) -> 8 | D6: SPM.NEW VICTORIA AVIARI | E6: MTA00101-10100022 | F6: 7.0885269e+08 | G6: 59071058 | H6: =RANK(G6,$G$4:$G$64,0) -> 3 | I6: 54550164 | J6: =RANK(I6,$I$4:$I$64,0) -> 4 | K6: =IFERROR(G6/I6-1," ") -> 0.082875901 | L6: =IFERROR(VLOOKUP(Table2[[#This Row],[CUST-GROUP]],$E$70:$K$88,7,FALSE),0) -> 0.14615526 | M6: =IFERROR(VLOOKUP(E6,STM!G:K,4,FALSE),0)/G6-1 -> 0.095355353 | N6: =IFERROR(VLOOKUP('SUMMARY MT 2026'!$B6,$E$70:$M$88,8,FALSE),0) -> -0.070447779 | O6: =IFERROR(VLOOKUP(E6,STM!G:K,5,FALSE),0)/G6-1 -> -0.80310319 | P6: =IFERROR(VLOOKUP('SUMMARY MT 2026'!$B6,$E$70:$M$88,9,FALSE),0) -> -0.62624123 | AK6: =IFERROR(VLOOKUP(E6,[1]dashboard_SYAIFUL!$E$4:$AZ$76,47,FALSE),0) -> 24 | AL6: =IFERROR(VLOOKUP(E6,[1]dashboard_SYAIFUL!$E$4:$AZ$76,48,FALSE),0) -> 11 | AM6: =IFERROR(VLOOKUP(E6,[1]dashboard_SYAIFUL!$E$4:$BD$76,49,FALSE),0) -> 18 | AN6: =IFERROR(VLOOKUP(E6,[1]dashboard_SYAIFUL!$E$4:$BD$76,50,FALSE),0) -> 17 | AO6: =IFERROR(VLOOKUP('SUMMARY MT 2026'!$E6,[1]dashboard_SYAIFUL!$E$4:$CP$76,89,FALSE),0) -> 12 | AP6: =IFERROR(VLOOKUP('SUMMARY MT 2026'!$E6,[1]dashboard_SYAIFUL!$E$4:$CP$76,90,FALSE),0) -> 23 | AR6: =35-Table2[[#This Row],[PARETO SKU MAR 2026]] -> 35 | AT6: =35-Table2[[#This Row],[PARETO SKU MAR 2026]] -> 35 | AV6: =35-Table2[[#This Row],[PARETO SKU MAR 2026]] -> 35 | AX6: =35-Table2[[#This Row],[PARETO SKU MAR 2026]] -> 35 | AZ6: =35-Table2[[#This Row],[PARETO SKU MAR 2026]] -> 35 | BB6: =35-Table2[[#This Row],[PARETO SKU MAR 2026]] -> 35 | BD6: =35-Table2[[#This Row],[PARETO SKU MAR 2026]] -> 35 | BF6: =35-Table2[[#This Row],[PARETO SKU MAR 2026]] -> 35 | BH6: =35-Table2[[#This Row],[PARETO SKU MAR 2026]] -> 35 | BJ6: =35-Table2[[#This Row],[PARETO SKU MAR 2026]] -> 35
B7: KL-TOP 100 | C7: =RANK(IFERROR(VLOOKUP(Table2[[#This Row],[CUSTNO_DIST]],STM!B:C,2,FALSE),0),STM!$C$5:$C$65,0) -> 4 | D7: PT.TOP SERATUS SEJATI GRAND BATAM MALL | E7: MTA00101-10100047 | F7: 7.0743437e+08 | G7: 58952864 | H7: =RANK(G7,$G$4:$G$64,0) -> 4 | I7: 60925634 | J7: =RANK(I7,$I$4:$I$64,0) -> 3 | K7: =IFERROR(G7/I7-1," ") -> -0.032379961 | L7: =IFERROR(VLOOKUP(Table2[[#This Row],[CUST-GROUP]],$E$70:$K$88,7,FALSE),0) -> 0.20819267 | M7: =IFERROR(VLOOKUP(E7,STM!G:K,4,FALSE),0)/G7-1 -> 0.37385425 | N7: =IFERROR(VLOOKUP('SUMMARY MT 2026'!$B7,$E$70:$M$88,8,FALSE),0) -> 0.23890659 | O7: =IFERROR(VLOOKUP(E7,STM!G:K,5,FALSE),0)/G7-1 -> -0.30512535 | P7: =IFERROR(VLOOKUP('SUMMARY MT 2026'!$B7,$E$70:$M$88,9,FALSE),0) -> -0.339362 | AK7: =IFERROR(VLOOKUP(E7,[1]dashboard_SYAIFUL!$E$4:$AZ$76,47,FALSE),0) -> 23 | AL7: =IFERROR(VLOOKUP(E7,[1]dashboard_SYAIFUL!$E$4:$AZ$76,48,FALSE),0) -> 12 | AM7: =IFERROR(VLOOKUP(E7,[1]dashboard_SYAIFUL!$E$4:$BD$76,49,FALSE),0) -> 20 | AN7: =IFERROR(VLOOKUP(E7,[1]dashboard_SYAIFUL!$E$4:$BD$76,50,FALSE),0) -> 15 | AO7: =IFERROR(VLOOKUP('SUMMARY MT 2026'!$E7,[1]dashboard_SYAIFUL!$E$4:$CP$76,89,FALSE),0) -> 14 | AP7: =IFERROR(VLOOKUP('SUMMARY MT 2026'!$E7,[1]dashboard_SYAIFUL!$E$4:$CP$76,90,FALSE),0) -> 21 | AR7: =35-Table2[[#This Row],[PARETO SKU MAR 2026]] -> 35 | AT7: =35-Table2[[#This Row],[PARETO SKU MAR 2026]] -> 35 | AV7: =35-Table2[[#This Row],[PARETO SKU MAR 2026]] -> 35 | AX7: =35-Table2[[#This Row],[PARETO SKU MAR 2026]] -> 35 | AZ7: =35-Table2[[#This Row],[PARETO SKU MAR 2026]] -> 35 | BB7: =35-Table2[[#This Row],[PARETO SKU MAR 2026]] -> 35 | BD7: =35-Table2[[#This Row],[PARETO SKU MAR 2026]] -> 35 | BF7: =35-Table2[[#This Row],[PARETO SKU MAR 2026]] -> 35 | BH7: =35-Table2[[#This Row],[PARETO SKU MAR 2026]] -> 35 | BJ7: =35-Table2[[#This Row],[PARETO SKU MAR 2026]] -> 35
B8: KL-TOP 100 | C8: =RANK(IFERROR(VLOOKUP(Table2[[#This Row],[CUSTNO_DIST]],STM!B:C,2,FALSE),0),STM!$C$5:$C$65,0) -> 5 | D8: PT.TOP SERATUS SEJATI TEMBESI | E8: MTA00101-10100031 | F8: 6.333572e+08 | G8: 52779766 | H8: =RANK(G8,$G$4:$G$64,0) -> 5 | I8: 37345714 | J8: =RANK(I8,$I$4:$I$64,0) -> 7 | K8: =IFERROR(G8/I8-1," ") -> 0.41327505 | L8: =IFERROR(VLOOKUP(Table2[[#This Row],[CUST-GROUP]],$E$70:$K$88,7,FALSE),0) -> 0.20819267 | M8: =IFERROR(VLOOKUP(E8,STM!G:K,4,FALSE),0)/G8-1 -> 0.160761 | N8: =IFERROR(VLOOKUP('SUMMARY MT 2026'!$B8,$E$70:$M$88,8,FALSE),0) -> 0.23890659 | O8: =IFERROR(VLOOKUP(E8,STM!G:K,5,FALSE),0)/G8-1 -> 0.017499818 | P8: =IFERROR(VLOOKUP('SUMMARY MT 2026'!$B8,$E$70:$M$88,9,FALSE),0) -> -0.339362 | AK8: =IFERROR(VLOOKUP(E8,[1]dashboard_SYAIFUL!$E$4:$AZ$76,47,FALSE),0) -> 31 | AL8: =IFERROR(VLOOKUP(E8,[1]dashboard_SYAIFUL!$E$4:$AZ$76,48,FALSE),0) -> 4 | AM8: =IFERROR(VLOOKUP(E8,[1]dashboard_SYAIFUL!$E$4:$BD$76,49,FALSE),0) -> 17 | AN8: =IFERROR(VLOOKUP(E8,[1]dashboard_SYAIFUL!$E$4:$BD$76,50,FALSE),0) -> 18 | AO8: =IFERROR(VLOOKUP('SUMMARY MT 2026'!$E8,[1]dashboard_SYAIFUL!$E$4:$CP$76,89,FALSE),0) -> 15 | AP8: =IFERROR(VLOOKUP('SUMMARY MT 2026'!$E8,[1]dashboard_SYAIFUL!$E$4:$CP$76,90,FALSE),0) -> 20 | AR8: =35-Table2[[#This Row],[PARETO SKU MAR 2026]] -> 35 | AT8: =35-Table2[[#This Row],[PARETO SKU MAR 2026]] -> 35 | AV8: =35-Table2[[#This Row],[PARETO SKU MAR 2026]] -> 35 | AX8: =35-Table2[[#This Row],[PARETO SKU MAR 2026]] -> 35 | AZ8: =35-Table2[[#This Row],[PARETO SKU MAR 2026]] -> 35 | BB8: =35-Table2[[#This Row],[PARETO SKU MAR 2026]] -> 35 | BD8: =35-Table2[[#This Row],[PARETO SKU MAR 2026]] -> 35 | BF8: =35-Table2[[#This Row],[PARETO SKU MAR 2026]] -> 35 | BH8: =35-Table2[[#This Row],[PARETO SKU MAR 2026]] -> 35 | BJ8: =35-Table2[[#This Row],[PARETO SKU MAR 2026]] -> 35
B9: KL-TOP 100 | C9: =RANK(IFERROR(VLOOKUP(Table2[[#This Row],[CUSTNO_DIST]],STM!B:C,2,FALSE),0),STM!$C$5:$C$65,0) -> 7 | D9: PT.TOP SERATUS SEJATI TANJUNG UNCANG | E9: MTA00101-10100048 | F9: 5.7589415e+08 | G9: 47991179 | H9: =RANK(G9,$G$4:$G$64,0) -> 6 | I9: 44011964 | J9: =RANK(I9,$I$4:$I$64,0) -> 5 | K9: =IFERROR(G9/I9-1," ") -> 0.090412125 | L9: =IFERROR(VLOOKUP(Table2[[#This Row],[CUST-GROUP]],$E$70:$K$88,7,FALSE),0) -> 0.20819267 | M9: =IFERROR(VLOOKUP(E9,STM!G:K,4,FALSE),0)/G9-1 -> 0.20743877 | N9: =IFERROR(VLOOKUP('SUMMARY MT 2026'!$B9,$E$70:$M$88,8,FALSE),0) -> 0.23890659 | O9: =IFERROR(VLOOKUP(E9,STM!G:K,5,FALSE),0)/G9-1 -> -0.2900631 | P9: =IFERROR(VLOOKUP('SUMMARY MT 2026'!$B9,$E$70:$M$88,9,FALSE),0) -> -0.339362 | AK9: =IFERROR(VLOOKUP(E9,[1]dashboard_SYAIFUL!$E$4:$AZ$76,47,FALSE),0) -> 25 | AL9: =IFERROR(VLOOKUP(E9,[1]dashboard_SYAIFUL!$E$4:$AZ$76,48,FALSE),0) -> 10 | AM9: =IFERROR(VLOOKUP(E9,[1]dashboard_SYAIFUL!$E$4:$BD$76,49,FALSE),0) -> 18 | AN9: =IFERROR(VLOOKUP(E9,[1]dashboard_SYAIFUL!$E$4:$BD$76,50,FALSE),0) -> 17 | AO9: =IFERROR(VLOOKUP('SUMMARY MT 2026'!$E9,[1]dashboard_SYAIFUL!$E$4:$CP$76,89,FALSE),0) -> 15 | AP9: =IFERROR(VLOOKUP('SUMMARY MT 2026'!$E9,[1]dashboard_SYAIFUL!$E$4:$CP$76,90,FALSE),0) -> 20 | AR9: =35-Table2[[#This Row],[PARETO SKU MAR 2026]] -> 35 | AT9: =35-Table2[[#This Row],[PARETO SKU MAR 2026]] -> 35 | AV9: =35-Table2[[#This Row],[PARETO SKU MAR 2026]] -> 35 | AX9: =35-Table2[[#This Row],[PARETO SKU MAR 2026]] -> 35 | AZ9: =35-Table2[[#This Row],[PARETO SKU MAR 2026]] -> 35 | BB9: =35-Table2[[#This Row],[PARETO SKU MAR 2026]] -> 35 | BD9: =35-Table2[[#This Row],[PARETO SKU MAR 2026]] -> 35 | BF9: =35-Table2[[#This Row],[PARETO SKU MAR 2026]] -> 35 | BH9: =35-Table2[[#This Row],[PARETO SKU MAR 2026]] -> 35 | BJ9: =35-Table2[[#This Row],[PARETO SKU MAR 2026]] -> 35
B10: KL-JODOH | C10: =RANK(IFERROR(VLOOKUP(Table2[[#This Row],[CUSTNO_DIST]],STM!B:C,2,FALSE),0),STM!$C$5:$C$65,0) -> 3 | D10: PT.JODOH CENTRE BALOI | E10: MTA00101-10100032 | F10: 5.5562462e+08 | G10: 46302052 | H10: =RANK(G10,$G$4:$G$64,0) -> 7 | I10: 40748850 | J10: =RANK(I10,$I$4:$I$64,0) -> 6 | K10: =IFERROR(G10/I10-1," ") -> 0.13627875 | L10: =IFERROR(VLOOKUP(Table2[[#This Row],[CUST-GROUP]],$E$70:$K$88,7,FALSE),0) -> 0.049144122 | M10: =IFERROR(VLOOKUP(E10,STM!G:K,4,FALSE),0)/G10-1 -> 1.3457367 | N10: =IFERROR(VLOOKUP('SUMMARY MT 2026'!$B10,$E$70:$M$88,8,FALSE),0) -> 0.68563098 | O10: =IFERROR(VLOOKUP(E10,STM!G:K,5,FALSE),0)/G10-1 -> -0.61183998 | P10: =IFERROR(VLOOKUP('SUMMARY MT 2026'!$B10,$E$70:$M$88,9,FALSE),0) -> -0.53480503 | AK10: =IFERROR(VLOOKUP(E10,[1]dashboard_SYAIFUL!$E$4:$AZ$76,47,FALSE),0) -> 31 | AL10: =IFERROR(VLOOKUP(E10,[1]dashboard_SYAIFUL!$E$4:$AZ$76,48,FALSE),0) -> 4 | AM10: =IFERROR(VLOOKUP(E10,[1]dashboard_SYAIFUL!$E$4:$BD$76,49,FALSE),0) -> 21 | AN10: =IFERROR(VLOOKUP(E10,[1]dashboard_SYAIFUL!$E$4:$BD$76,50,FALSE),0) -> 14 | AO10: =IFERROR(VLOOKUP('SUMMARY MT 2026'!$E10,[1]dashboard_SYAIFUL!$E$4:$CP$76,89,FALSE),0) -> 12 | AP10: =IFERROR(VLOOKUP('SUMMARY MT 2026'!$E10,[1]dashboard_SYAIFUL!$E$4:$CP$76,90,FALSE),0) -> 23 | AR10: =35-Table2[[#This Row],[PARETO SKU MAR 2026]] -> 35 | AT10: =35-Table2[[#This Row],[PARETO SKU MAR 2026]] -> 35 | AV10: =35-Table2[[#This Row],[PARETO SKU MAR 2026]] -> 35 | AX10: =35-Table2[[#This Row],[PARETO SKU MAR 2026]] -> 35 | AZ10: =35-Table2[[#This Row],[PARETO SKU MAR 2026]] -> 35 | BB10: =35-Table2[[#This Row],[PARETO SKU MAR 2026]] -> 35 | BD10: =35-Table2[[#This Row],[PARETO SKU MAR 2026]] -> 35 | BF10: =35-Table2[[#This Row],[PARETO SKU MAR 2026]] -> 35 | BH10: =35-Table2[[#This Row],[PARETO SKU MAR 2026]] -> 35 | BJ10: =35-Table2[[#This Row],[PARETO SKU MAR 2026]] -> 35
B11: KL-VICTORIA | C11: =RANK(IFERROR(VLOOKUP(Table2[[#This Row],[CUSTNO_DIST]],STM!B:C,2,FALSE),0),STM!$C$5:$C$65,0) -> 9 | D11: MM.VICTORIA FANINDO | E11: MTA00101-10100034 | F11: 5.4986711e+08 | G11: 45822259 | H11: =RANK(G11,$G$4:$G$64,0) -> 8 | I11: 29924627 | J11: =RANK(I11,$I$4:$I$64,0) -> 10 | K11: =IFERROR(G11/I11-1," ") -> 0.53125582 | L11: =IFERROR(VLOOKUP(Table2[[#This Row],[CUST-GROUP]],$E$70:$K$88,7,FALSE),0) -> 0.14615526 | M11: =IFERROR(VLOOKUP(E11,STM!G:K,4,FALSE),0)/G11-1 -> -0.11889075 | N11: =IFERROR(VLOOKUP('SUMMARY MT 2026'!$B11,$E$70:$M$88,8,FALSE),0) -> -0.070447779 | O11: =IFERROR(VLOOKUP(E11,STM!G:K,5,FALSE),0)/G11-1 -> -0.42988851 | P11: =IFERROR(VLOOKUP('SUMMARY MT 2026'!$B11,$E$70:$M$88,9,FALSE),0) -> -0.62624123 | AK11: =IFERROR(VLOOKUP(E11,[1]dashboard_SYAIFUL!$E$4:$AZ$76,47,FALSE),0) -> 26 | AL11: =IFERROR(VLOOKUP(E11,[1]dashboard_SYAIFUL!$E$4:$AZ$76,48,FALSE),0) -> 9 | AM11: =IFERROR(VLOOKUP(E11,[1]dashboard_SYAIFUL!$E$4:$BD$76,49,FALSE),0) -> 15 | AN11: =IFERROR(VLOOKUP(E11,[1]dashboard_SYAIFUL!$E$4:$BD$76,50,FALSE),0) -> 20 | AO11: =IFERROR(VLOOKUP('SUMMARY MT 2026'!$E11,[1]dashboard_SYAIFUL!$E$4:$CP$76,89,FALSE),0) -> 10 | AP11: =IFERROR(VLOOKUP('SUMMARY MT 2026'!$E11,[1]dashboard_SYAIFUL!$E$4:$CP$76,90,FALSE),0) -> 25 | AR11: =35-Table2[[#This Row],[PARETO SKU MAR 2026]] -> 35 | AT11: =35-Table2[[#This Row],[PARETO SKU MAR 2026]] -> 35 | AV11: =35-Table2[[#This Row],[PARETO SKU MAR 2026]] -> 35 | AX11: =35-Table2[[#This Row],[PARETO SKU MAR 2026]] -> 35 | AZ11: =35-Table2[[#This Row],[PARETO SKU MAR 2026]] -> 35 | BB11: =35-Table2[[#This Row],[PARETO SKU MAR 2026]] -> 35 | BD11: =35-Table2[[#This Row],[PARETO SKU MAR 2026]] -> 35 | BF11: =35-Table2[[#This Row],[PARETO SKU MAR 2026]] -> 35 | BH11: =35-Table2[[#This Row],[PARETO SKU MAR 2026]] -> 35 | BJ11: =35-Table2[[#This Row],[PARETO SKU MAR 2026]] -> 35
B12: KL-GOGO | C12: =RANK(IFERROR(VLOOKUP(Table2[[#This Row],[CUSTNO_DIST]],STM!B:C,2,FALSE),0),STM!$C$5:$C$65,0) -> 13 | D12: SUPERMARKET GOGO SERAYA | E12: MTA00101-10100045 | F12: 4.287372e+08 | G12: 35728100 | H12: =RANK(G12,$G$4:$G$64,0) -> 9 | I12: 30554786 | J12: =RANK(I12,$I$4:$I$64,0) -> 9 | K12: =IFERROR(G12/I12-1," ") -> 0.16931274 | L12: =IFERROR(VLOOKUP(Table2[[#This Row],[CUST-GROUP]],$E$70:$K$88,7,FALSE),0) -> 0.31105347 | M12: =IFERROR(VLOOKUP(E12,STM!G:K,4,FALSE),0)/G12-1 -> -0.14045486 | N12: =IFERROR(VLOOKUP('SUMMARY MT 2026'!$B12,$E$70:$M$88,8,FALSE),0) -> -0.202461 | O12: =IFERROR(VLOOKUP(E12,STM!G:K,5,FALSE),0)/G12-1 -> -0.48677445 | P12: =IFERROR(VLOOKUP('SUMMARY MT 2026'!$B12,$E$70:$M$88,9,FALSE),0) -> -0.48667136 | AK12: =IFERROR(VLOOKUP(E12,[1]dashboard_SYAIFUL!$E$4:$AZ$76,47,FALSE),0) -> 31 | AL12: =IFERROR(VLOOKUP(E12,[1]dashboard_SYAIFUL!$E$4:$AZ$76,48,FALSE),0) -> 4 | AM12: =IFERROR(VLOOKUP(E12,[1]dashboard_SYAIFUL!$E$4:$BD$76,49,FALSE),0) -> 17 | AN12: =IFERROR(VLOOKUP(E12,[1]dashboard_SYAIFUL!$E$4:$BD$76,50,FALSE),0) -> 18 | AO12: =IFERROR(VLOOKUP('SUMMARY MT 2026'!$E12,[1]dashboard_SYAIFUL!$E$4:$CP$76,89,FALSE),0) -> 15 | AP12: =IFERROR(VLOOKUP('SUMMARY MT 2026'!$E12,[1]dashboard_SYAIFUL!$E$4:$CP$76,90,FALSE),0) -> 20 | AR12: =35-Table2[[#This Row],[PARETO SKU MAR 2026]] -> 35 | AT12: =35-Table2[[#This Row],[PARETO SKU MAR 2026]] -> 35 | AV12: =35-Table2[[#This Row],[PARETO SKU MAR 2026]] -> 35 | AX12: =35-Table2[[#This Row],[PARETO SKU MAR 2026]] -> 35 | AZ12: =35-Table2[[#This Row],[PARETO SKU MAR 2026]] -> 35 | BB12: =35-Table2[[#This Row],[PARETO SKU MAR 2026]] -> 35 | BD12: =35-Table2[[#This Row],[PARETO SKU MAR 2026]] -> 35 | BF12: =35-Table2[[#This Row],[PARETO SKU MAR 2026]] -> 35 | BH12: =35-Table2[[#This Row],[PARETO SKU MAR 2026]] -> 35 | BJ12: =35-Table2[[#This Row],[PARETO SKU MAR 2026]] -> 35
B13: KA-DIAMOND | C13: =RANK(IFERROR(VLOOKUP(Table2[[#This Row],[CUSTNO_DIST]],STM!B:C,2,FALSE),0),STM!$C$5:$C$65,0) -> 12 | D13: PT.KURNIAPHILEO SELARAS DC MALL | E13: MTA00101-10100026 | F13: 4.1443686e+08 | G13: 34536405 | H13: =RANK(G13,$G$4:$G$64,0) -> 10 | I13: 28966063 | J13: =RANK(I13,$I$4:$I$64,0) -> 11 | K13: =IFERROR(G13/I13-1," ") -> 0.19230579 | L13: =IFERROR(VLOOKUP(Table2[[#This Row],[CUST-GROUP]],$E$70:$K$88,7,FALSE),0) -> 0.19230579 | M13: =IFERROR(VLOOKUP(E13,STM!G:K,4,FALSE),0)/G13-1 -> 0.044488562 | N13: =IFERROR(VLOOKUP('SUMMARY MT 2026'!$B13,$E$70:$M$88,8,FALSE),0) -> 0.044488562 | O13: =IFERROR(VLOOKUP(E13,STM!G:K,5,FALSE),0)/G13-1 -> -0.6092282 | P13: =IFERROR(VLOOKUP('SUMMARY MT 2026'!$B13,$E$70:$M$88,9,FALSE),0) -> -0.6092282 | AK13: =IFERROR(VLOOKUP(E13,[1]dashboard_SYAIFUL!$E$4:$AZ$76,47,FALSE),0) -> 23 | AL13: =IFERROR(VLOOKUP(E13,[1]dashboard_SYAIFUL!$E$4:$AZ$76,48,FALSE),0) -> 12 | AM13: =IFERROR(VLOOKUP(E13,[1]dashboard_SYAIFUL!$E$4:$BD$76,49,FALSE),0) -> 18 | AN13: =IFERROR(VLOOKUP(E13,[1]dashboard_SYAIFUL!$E$4:$BD$76,50,FALSE),0) -> 17 | AO13: =IFERROR(VLOOKUP('SUMMARY MT 2026'!$E13,[1]dashboard_SYAIFUL!$E$4:$CP$76,89,FALSE),0) -> 15 | AP13: =IFERROR(VLOOKUP('SUMMARY MT 2026'!$E13,[1]dashboard_SYAIFUL!$E$4:$CP$76,90,FALSE),0) -> 20 | AR13: =35-Table2[[#This Row],[PARETO SKU MAR 2026]] -> 35 | AT13: =35-Table2[[#This Row],[PARETO SKU MAR 2026]] -> 35 | AV13: =35-Table2[[#This Row],[PARETO SKU MAR 2026]] -> 35 | AX13: =35-Table2[[#This Row],[PARETO SKU MAR 2026]] -> 35 | AZ13: =35-Table2[[#This Row],[PARETO SKU MAR 2026]] -> 35 | BB13: =35-Table2[[#This Row],[PARETO SKU MAR 2026]] -> 35 | BD13: =35-Table2[[#This Row],[PARETO SKU MAR 2026]] -> 35 | BF13: =35-Table2[[#This Row],[PARETO SKU MAR 2026]] -> 35 | BH13: =35-Table2[[#This Row],[PARETO SKU MAR 2026]] -> 35 | BJ13: =35-Table2[[#This Row],[PARETO SKU MAR 2026]] -> 35
B14: KL-TOP 100 | C14: =RANK(IFERROR(VLOOKUP(Table2[[#This Row],[CUSTNO_DIST]],STM!B:C,2,FALSE),0),STM!$C$5:$C$65,0) -> 6 | D14: PT.TOP SERATUS SEJATI GARDEN AVENUE | E14: MTA00101-10100064 | F14: 3.9205798e+08 | G14: 32671498 | H14: =RANK(G14,$G$4:$G$64,0) -> 11 | I14: 0 | J14: =RANK(I14,$I$4:$I$64,0) -> 58 | K14: =IFERROR(G14/I14-1,1) -> 1 | L14: =IFERROR(VLOOKUP(Table2[[#This Row],[CUST-GROUP]],$E$70:$K$88,7,FALSE),0) -> 0.20819267 | M14: =IFERROR(VLOOKUP(E14,STM!G:K,4,FALSE),0)/G14-1 -> 1.5031723 | N14: =IFERROR(VLOOKUP('SUMMARY MT 2026'!$B14,$E$70:$M$88,8,FALSE),0) -> 0.23890659 | O14: =IFERROR(VLOOKUP(E14,STM!G:K,5,FALSE),0)/G14-1 -> -0.68234137 | P14: =IFERROR(VLOOKUP('SUMMARY MT 2026'!$B14,$E$70:$M$88,9,FALSE),0) -> -0.339362 | AK14: =IFERROR(VLOOKUP(E14,[1]dashboard_SYAIFUL!$E$4:$AZ$76,47,FALSE),0) -> 29 | AL14: =IFERROR(VLOOKUP(E14,[1]dashboard_SYAIFUL!$E$4:$AZ$76,48,FALSE),0) -> 6 | AM14: =IFERROR(VLOOKUP(E14,[1]dashboard_SYAIFUL!$E$4:$BD$76,49,FALSE),0) -> 12 | AN14: =IFERROR(VLOOKUP(E14,[1]dashboard_SYAIFUL!$E$4:$BD$76,50,FALSE),0) -> 23 | AO14: =IFERROR(VLOOKUP('SUMMARY MT 2026'!$E14,[1]dashboard_SYAIFUL!$E$4:$CP$76,89,FALSE),0) -> 3 | AP14: =IFERROR(VLOOKUP('SUMMARY MT 2026'!$E14,[1]dashboard_SYAIFUL!$E$4:$CP$76,90,FALSE),0) -> 32 | AR14: =35-Table2[[#This Row],[PARETO SKU MAR 2026]] -> 35 | AT14: =35-Table2[[#This Row],[PARETO SKU MAR 2026]] -> 35 | AV14: =35-Table2[[#This Row],[PARETO SKU MAR 2026]] -> 35 | AX14: =35-Table2[[#This Row],[PARETO SKU MAR 2026]] -> 35 | AZ14: =35-Table2[[#This Row],[PARETO SKU MAR 2026]] -> 35 | BB14: =35-Table2[[#This Row],[PARETO SKU MAR 2026]] -> 35 | BD14: =35-Table2[[#This Row],[PARETO SKU MAR 2026]] -> 35 | BF14: =35-Table2[[#This Row],[PARETO SKU MAR 2026]] -> 35 | BH14: =35-Table2[[#This Row],[PARETO SKU MAR 2026]] -> 35 | BJ14: =35-Table2[[#This Row],[PARETO SKU MAR 2026]] -> 35
B15: KL-VICTORIA | C15: =RANK(IFERROR(VLOOKUP(Table2[[#This Row],[CUSTNO_DIST]],STM!B:C,2,FALSE),0),STM!$C$5:$C$65,0) -> 11 | D15: MM.NEW VICTORIA | E15: MTA00101-10100046 | F15: 3.9033057e+08 | G15: 32527548 | H15: =RANK(G15,$G$4:$G$64,0) -> 12 | I15: 32951749 | J15: =RANK(I15,$I$4:$I$64,0) -> 8 | K15: =IFERROR(G15/I15-1," ") -> -0.012873397 | L15: =IFERROR(VLOOKUP(Table2[[#This Row],[CUST-GROUP]],$E$70:$K$88,7,FALSE),0) -> 0.14615526 | M15: =IFERROR(VLOOKUP(E15,STM!G:K,4,FALSE),0)/G15-1 -> -0.071074308 | N15: =IFERROR(VLOOKUP('SUMMARY MT 2026'!$B15,$E$70:$M$88,8,FALSE),0) -> -0.070447779 | O15: =IFERROR(VLOOKUP(E15,STM!G:K,5,FALSE),0)/G15-1 -> -0.36914161 | P15: =IFERROR(VLOOKUP('SUMMARY MT 2026'!$B15,$E$70:$M$88,9,FALSE),0) -> -0.62624123 | AK15: =IFERROR(VLOOKUP(E15,[1]dashboard_SYAIFUL!$E$4:$AZ$76,47,FALSE),0) -> 24 | AL15: =IFERROR(VLOOKUP(E15,[1]dashboard_SYAIFUL!$E$4:$AZ$76,48,FALSE),0) -> 11 | AM15: =IFERROR(VLOOKUP(E15,[1]dashboard_SYAIFUL!$E$4:$BD$76,49,FALSE),0) -> 13 | AN15: =IFERROR(VLOOKUP(E15,[1]dashboard_SYAIFUL!$E$4:$BD$76,50,FALSE),0) -> 22 | AO15: =IFERROR(VLOOKUP('SUMMARY MT 2026'!$E15,[1]dashboard_SYAIFUL!$E$4:$CP$76,89,FALSE),0) -> 8 | AP15: =IFERROR(VLOOKUP('SUMMARY MT 2026'!$E15,[1]dashboard_SYAIFUL!$E$4:$CP$76,90,FALSE),0) -> 27 | AR15: =35-Table2[[#This Row],[PARETO SKU MAR 2026]] -> 35 | AT15: =35-Table2[[#This Row],[PARETO SKU MAR 2026]] -> 35 | AV15: =35-Table2[[#This Row],[PARETO SKU MAR 2026]] -> 35 | AX15: =35-Table2[[#This Row],[PARETO SKU MAR 2026]] -> 35 | AZ15: =35-Table2[[#This Row],[PARETO SKU MAR 2026]] -> 35 | BB15: =35-Table2[[#This Row],[PARETO SKU MAR 2026]] -> 35 | BD15: =35-Table2[[#This Row],[PARETO SKU MAR 2026]] -> 35 | BF15: =35-Table2[[#This Row],[PARETO SKU MAR 2026]] -> 35 | BH15: =35-Table2[[#This Row],[PARETO SKU MAR 2026]] -> 35 | BJ15: =35-Table2[[#This Row],[PARETO SKU MAR 2026]] -> 35
B16: KL-GOGO | C16: =RANK(IFERROR(VLOOKUP(Table2[[#This Row],[CUSTNO_DIST]],STM!B:C,2,FALSE),0),STM!$C$5:$C$65,0) -> 22 | D16: SUPERMARKET GOGO GOLDEN CITY | E16: MTA00101-10100019 | F16: 3.6788753e+08 | G16: 30657294 | H16: =RANK(G16,$G$4:$G$64,0) -> 13 | I16: 20101131 | J16: =RANK(I16,$I$4:$I$64,0) -> 17 | K16: =IFERROR(G16/I16-1," ") -> 0.52515268 | L16: =IFERROR(VLOOKUP(Table2[[#This Row],[CUST-GROUP]],$E$70:$K$88,7,FALSE),0) -> 0.31105347 | M16: =IFERROR(VLOOKUP(E16,STM!G:K,4,FALSE),0)/G16-1 -> -0.35441491 | N16: =IFERROR(VLOOKUP('SUMMARY MT 2026'!$B16,$E$70:$M$88,8,FALSE),0) -> -0.202461 | O16: =IFERROR(VLOOKUP(E16,STM!G:K,5,FALSE),0)/G16-1 -> -0.75238022 | P16: =IFERROR(VLOOKUP('SUMMARY MT 2026'!$B16,$E$70:$M$88,9,FALSE),0) -> -0.48667136 | AK16: =IFERROR(VLOOKUP(E16,[1]dashboard_SYAIFUL!$E$4:$AZ$76,47,FALSE),0) -> 31 | AL16: =IFERROR(VLOOKUP(E16,[1]dashboard_SYAIFUL!$E$4:$AZ$76,48,FALSE),0) -> 4 | AM16: =IFERROR(VLOOKUP(E16,[1]dashboard_SYAIFUL!$E$4:$BD$76,49,FALSE),0) -> 18 | AN16: =IFERROR(VLOOKUP(E16,[1]dashboard_SYAIFUL!$E$4:$BD$76,50,FALSE),0) -> 17 | AO16: =IFERROR(VLOOKUP('SUMMARY MT 2026'!$E16,[1]dashboard_SYAIFUL!$E$4:$CP$76,89,FALSE),0) -> 14 | AP16: =IFERROR(VLOOKUP('SUMMARY MT 2026'!$E16,[1]dashboard_SYAIFUL!$E$4:$CP$76,90,FALSE),0) -> 21 | AR16: =35-Table2[[#This Row],[PARETO SKU MAR 2026]] -> 35 | AT16: =35-Table2[[#This Row],[PARETO SKU MAR 2026]] -> 35 | AV16: =35-Table2[[#This Row],[PARETO SKU MAR 2026]] -> 35 | AX16: =35-Table2[[#This Row],[PARETO SKU MAR 2026]] -> 35 | AZ16: =35-Table2[[#This Row],[PARETO SKU MAR 2026]] -> 35 | BB16: =35-Table2[[#This Row],[PARETO SKU MAR 2026]] -> 35 | BD16: =35-Table2[[#This Row],[PARETO SKU MAR 2026]] -> 35 | BF16: =35-Table2[[#This Row],[PARETO SKU MAR 2026]] -> 35 | BH16: =35-Table2[[#This Row],[PARETO SKU MAR 2026]] -> 35 | BJ16: =35-Table2[[#This Row],[PARETO SKU MAR 2026]] -> 35
B17: KL-TOP 100 | C17: =RANK(IFERROR(VLOOKUP(Table2[[#This Row],[CUSTNO_DIST]],STM!B:C,2,FALSE),0),STM!$C$5:$C$65,0) -> 20 | D17: PT.TOP SERATUS SEJATI NIAGA MAS | E17: MTA00101-10100029 | F17: 3.1529238e+08 | G17: 26274365 | H17: =RANK(G17,$G$4:$G$64,0) -> 14 | I17: 26666710 | J17: =RANK(I17,$I$4:$I$64,0) -> 12 | K17: =IFERROR(G17/I17-1," ") -> -0.014712902 | L17: =IFERROR(VLOOKUP(Table2[[#This Row],[CUST-GROUP]],$E$70:$K$88,7,FALSE),0) -> 0.20819267 | M17: =IFERROR(VLOOKUP(E17,STM!G:K,4,FALSE),0)/G17-1 -> -0.043043656 | N17: =IFERROR(VLOOKUP('SUMMARY MT 2026'!$B17,$E$70:$M$88,8,FALSE),0) -> 0.23890659 | O17: =IFERROR(VLOOKUP(E17,STM!G:K,5,FALSE),0)/G17-1 -> -0.74794059 | P17: =IFERROR(VLOOKUP('SUMMARY MT 2026'!$B17,$E$70:$M$88,9,FALSE),0) -> -0.339362 | AK17: =IFERROR(VLOOKUP(E17,[1]dashboard_SYAIFUL!$E$4:$AZ$76,47,FALSE),0) -> 21 | AL17: =IFERROR(VLOOKUP(E17,[1]dashboard_SYAIFUL!$E$4:$AZ$76,48,FALSE),0) -> 14 | AM17: =IFERROR(VLOOKUP(E17,[1]dashboard_SYAIFUL!$E$4:$BD$76,49,FALSE),0) -> 16 | AN17: =IFERROR(VLOOKUP(E17,[1]dashboard_SYAIFUL!$E$4:$BD$76,50,FALSE),0) -> 19 | AO17: =IFERROR(VLOOKUP('SUMMARY MT 2026'!$E17,[1]dashboard_SYAIFUL!$E$4:$CP$76,89,FALSE),0) -> 10 | AP17: =IFERROR(VLOOKUP('SUMMARY MT 2026'!$E17,[1]dashboard_SYAIFUL!$E$4:$CP$76,90,FALSE),0) -> 25 | AR17: =35-Table2[[#This Row],[PARETO SKU MAR 2026]] -> 35 | AT17: =35-Table2[[#This Row],[PARETO SKU MAR 2026]] -> 35 | AV17: =35-Table2[[#This Row],[PARETO SKU MAR 2026]] -> 35 | AX17: =35-Table2[[#This Row],[PARETO SKU MAR 2026]] -> 35 | AZ17: =35-Table2[[#This Row],[PARETO SKU MAR 2026]] -> 35 | BB17: =35-Table2[[#This Row],[PARETO SKU MAR 2026]] -> 35 | BD17: =35-Table2[[#This Row],[PARETO SKU MAR 2026]] -> 35 | BF17: =35-Table2[[#This Row],[PARETO SKU MAR 2026]] -> 35 | BH17: =35-Table2[[#This Row],[PARETO SKU MAR 2026]] -> 35 | BJ17: =35-Table2[[#This Row],[PARETO SKU MAR 2026]] -> 35
B18: KL-INDAH | C18: =RANK(IFERROR(VLOOKUP(Table2[[#This Row],[CUSTNO_DIST]],STM!B:C,2,FALSE),0),STM!$C$5:$C$65,0) -> 18 | D18: PT.ROYAL SUPERMARKET - DAPUR 12 | E18: MTA00101-10100040 | F18: 3.1262335e+08 | G18: 26051946 | H18: =RANK(G18,$G$4:$G$64,0) -> 15 | I18: 21370074 | J18: =RANK(I18,$I$4:$I$64,0) -> 15 | K18: =IFERROR(G18/I18-1," ") -> 0.21908545 | L18: =IFERROR(VLOOKUP(Table2[[#This Row],[CUST-GROUP]],$E$70:$K$88,7,FALSE),0) -> 0.03542864 | M18: =IFERROR(VLOOKUP(E18,STM!G:K,4,FALSE),0)/G18-1 -> -0.48028986 | N18: =IFERROR(VLOOKUP('SUMMARY MT 2026'!$B18,$E$70:$M$88,8,FALSE),0) -> -0.15994414 | O18: =IFERROR(VLOOKUP(E18,STM!G:K,5,FALSE),0)/G18-1 -> -0.081398265 | P18: =IFERROR(VLOOKUP('SUMMARY MT 2026'!$B18,$E$70:$M$88,9,FALSE),0) -> -0.14096078 | AK18: =IFERROR(VLOOKUP(E18,[1]dashboard_SYAIFUL!$E$4:$AZ$76,47,FALSE),0) -> 14 | AL18: =IFERROR(VLOOKUP(E18,[1]dashboard_SYAIFUL!$E$4:$AZ$76,48,FALSE),0) -> 21 | AM18: =IFERROR(VLOOKUP(E18,[1]dashboard_SYAIFUL!$E$4:$BD$76,49,FALSE),0) -> 9 | AN18: =IFERROR(VLOOKUP(E18,[1]dashboard_SYAIFUL!$E$4:$BD$76,50,FALSE),0) -> 26 | AO18: =IFERROR(VLOOKUP('SUMMARY MT 2026'!$E18,[1]dashboard_SYAIFUL!$E$4:$CP$76,89,FALSE),0) -> 8 | AP18: =IFERROR(VLOOKUP('SUMMARY MT 2026'!$E18,[1]dashboard_SYAIFUL!$E$4:$CP$76,90,FALSE),0) -> 27 | AR18: =35-Table2[[#This Row],[PARETO SKU MAR 2026]] -> 35 | AT18: =35-Table2[[#This Row],[PARETO SKU MAR 2026]] -> 35 | AV18: =35-Table2[[#This Row],[PARETO SKU MAR 2026]] -> 35 | AX18: =35-Table2[[#This Row],[PARETO SKU MAR 2026]] -> 35 | AZ18: =35-Table2[[#This Row],[PARETO SKU MAR 2026]] -> 35 | BB18: =35-Table2[[#This Row],[PARETO SKU MAR 2026]] -> 35 | BD18: =35-Table2[[#This Row],[PARETO SKU MAR 2026]] -> 35 | BF18: =35-Table2[[#This Row],[PARETO SKU MAR 2026]] -> 35 | BH18: =35-Table2[[#This Row],[PARETO SKU MAR 2026]] -> 35 | BJ18: =35-Table2[[#This Row],[PARETO SKU MAR 2026]] -> 35
B19: KL-TOP 100 | C19: =RANK(IFERROR(VLOOKUP(Table2[[#This Row],[CUSTNO_DIST]],STM!B:C,2,FALSE),0),STM!$C$5:$C$65,0) -> 30 | D19: PT.TOP SERATUS SEJATI BENGKONG | E19: MTA00101-10100033 | F19: 2.6076906e+08 | G19: 21730755 | H19: =RANK(G19,$G$4:$G$64,0) -> 16 | I19: 23089016 | J19: =RANK(I19,$I$4:$I$64,0) -> 13 | K19: =IFERROR(G19/I19-1," ") -> -0.058827159 | L19: =IFERROR(VLOOKUP(Table2[[#This Row],[CUST-GROUP]],$E$70:$K$88,7,FALSE),0) -> 0.20819267 | M19: =IFERROR(VLOOKUP(E19,STM!G:K,4,FALSE),0)/G19-1 -> -0.32668216 | N19: =IFERROR(VLOOKUP('SUMMARY MT 2026'!$B19,$E$70:$M$88,8,FALSE),0) -> 0.23890659 | O19: =IFERROR(VLOOKUP(E19,STM!G:K,5,FALSE),0)/G19-1 -> -0.75053418 | P19: =IFERROR(VLOOKUP('SUMMARY MT 2026'!$B19,$E$70:$M$88,9,FALSE),0) -> -0.339362 | AK19: =IFERROR(VLOOKUP(E19,[1]dashboard_SYAIFUL!$E$4:$AZ$76,47,FALSE),0) -> 22 | AL19: =IFERROR(VLOOKUP(E19,[1]dashboard_SYAIFUL!$E$4:$AZ$76,48,FALSE),0) -> 13 | AM19: =IFERROR(VLOOKUP(E19,[1]dashboard_SYAIFUL!$E$4:$BD$76,49,FALSE),0) -> 11 | AN19: =IFERROR(VLOOKUP(E19,[1]dashboard_SYAIFUL!$E$4:$BD$76,50,FALSE),0) -> 24 | AO19: =IFERROR(VLOOKUP('SUMMARY MT 2026'!$E19,[1]dashboard_SYAIFUL!$E$4:$CP$76,89,FALSE),0) -> 8 | AP19: =IFERROR(VLOOKUP('SUMMARY MT 2026'!$E19,[1]dashboard_SYAIFUL!$E$4:$CP$76,90,FALSE),0) -> 27 | AR19: =35-Table2[[#This Row],[PARETO SKU MAR 2026]] -> 35 | AT19: =35-Table2[[#This Row],[PARETO SKU MAR 2026]] -> 35 | AV19: =35-Table2[[#This Row],[PARETO SKU MAR 2026]] -> 35 | AX19: =35-Table2[[#This Row],[PARETO SKU MAR 2026]] -> 35 | AZ19: =35-Table2[[#This Row],[PARETO SKU MAR 2026]] -> 35 | BB19: =35-Table2[[#This Row],[PARETO SKU MAR 2026]] -> 35 | BD19: =35-Table2[[#This Row],[PARETO SKU MAR 2026]] -> 35 | BF19: =35-Table2[[#This Row],[PARETO SKU MAR 2026]] -> 35 | BH19: =35-Table2[[#This Row],[PARETO SKU MAR 2026]] -> 35 | BJ19: =35-Table2[[#This Row],[PARETO SKU MAR 2026]] -> 35
B20: KL-STAR | C20: =RANK(IFERROR(VLOOKUP(Table2[[#This Row],[CUSTNO_DIST]],STM!B:C,2,FALSE),0),STM!$C$5:$C$65,0) -> 14 | D20: MM.BPS NAGOYA | E20: MTA00101-10100044 | F20: 2.4209436e+08 | G20: 20174530 | H20: =RANK(G20,$G$4:$G$64,0) -> 17 | I20: 22085130 | J20: =RANK(I20,$I$4:$I$64,0) -> 14 | K20: =IFERROR(G20/I20-1," ") -> -0.086510701 | L20: =IFERROR(VLOOKUP(Table2[[#This Row],[CUST-GROUP]],$E$70:$K$88,7,FALSE),0) -> 0.12954458 | M20: =IFERROR(VLOOKUP(E20,STM!G:K,4,FALSE),0)/G20-1 -> 0.90714967 | N20: =IFERROR(VLOOKUP('SUMMARY MT 2026'!$B20,$E$70:$M$88,8,FALSE),0) -> 0.47930017 | O20: =IFERROR(VLOOKUP(E20,STM!G:K,5,FALSE),0)/G20-1 -> -0.57209917 | P20: =IFERROR(VLOOKUP('SUMMARY MT 2026'!$B20,$E$70:$M$88,9,FALSE),0) -> -0.13220472 | AK20: =IFERROR(VLOOKUP(E20,[1]dashboard_SYAIFUL!$E$4:$AZ$76,47,FALSE),0) -> 19 | AL20: =IFERROR(VLOOKUP(E20,[1]dashboard_SYAIFUL!$E$4:$AZ$76,48,FALSE),0) -> 16 | AM20: =IFERROR(VLOOKUP(E20,[1]dashboard_SYAIFUL!$E$4:$BD$76,49,FALSE),0) -> 10 | AN20: =IFERROR(VLOOKUP(E20,[1]dashboard_SYAIFUL!$E$4:$BD$76,50,FALSE),0) -> 25 | AO20: =IFERROR(VLOOKUP('SUMMARY MT 2026'!$E20,[1]dashboard_SYAIFUL!$E$4:$CP$76,89,FALSE),0) -> 7 | AP20: =IFERROR(VLOOKUP('SUMMARY MT 2026'!$E20,[1]dashboard_SYAIFUL!$E$4:$CP$76,90,FALSE),0) -> 28 | AR20: =35-Table2[[#This Row],[PARETO SKU MAR 2026]] -> 35 | AT20: =35-Table2[[#This Row],[PARETO SKU MAR 2026]] -> 35 | AV20: =35-Table2[[#This Row],[PARETO SKU MAR 2026]] -> 35 | AX20: =35-Table2[[#This Row],[PARETO SKU MAR 2026]] -> 35 | AZ20: =35-Table2[[#This Row],[PARETO SKU MAR 2026]] -> 35 | BB20: =35-Table2[[#This Row],[PARETO SKU MAR 2026]] -> 35 | BD20: =35-Table2[[#This Row],[PARETO SKU MAR 2026]] -> 35 | BF20: =35-Table2[[#This Row],[PARETO SKU MAR 2026]] -> 35 | BH20: =35-Table2[[#This Row],[PARETO SKU MAR 2026]] -> 35 | BJ20: =35-Table2[[#This Row],[PARETO SKU MAR 2026]] -> 35
B21: KL-JODOH | C21: =RANK(IFERROR(VLOOKUP(Table2[[#This Row],[CUSTNO_DIST]],STM!B:C,2,FALSE),0),STM!$C$5:$C$65,0) -> 28 | D21: PT.JODOH CENTRE ONE BATAM MALL | E21: MTA00101-10100010 | F21: 2.2845815e+08 | G21: 19038179 | H21: =RANK(G21,$G$4:$G$64,0) -> 18 | I21: 21330400 | J21: =RANK(I21,$I$4:$I$64,0) -> 16 | K21: =IFERROR(G21/I21-1," ") -> -0.1074626 | L21: =IFERROR(VLOOKUP(Table2[[#This Row],[CUST-GROUP]],$E$70:$K$88,7,FALSE),0) -> 0.049144122 | M21: =IFERROR(VLOOKUP(E21,STM!G:K,4,FALSE),0)/G21-1 -> -0.40606797 | N21: =IFERROR(VLOOKUP('SUMMARY MT 2026'!$B21,$E$70:$M$88,8,FALSE),0) -> 0.68563098 | O21: =IFERROR(VLOOKUP(E21,STM!G:K,5,FALSE),0)/G21-1 -> -0.42505286 | P21: =IFERROR(VLOOKUP('SUMMARY MT 2026'!$B21,$E$70:$M$88,9,FALSE),0) -> -0.53480503 | AK21: =IFERROR(VLOOKUP(E21,[1]dashboard_SYAIFUL!$E$4:$AZ$76,47,FALSE),0) -> 20 | AL21: =IFERROR(VLOOKUP(E21,[1]dashboard_SYAIFUL!$E$4:$AZ$76,48,FALSE),0) -> 15 | AM21: =IFERROR(VLOOKUP(E21,[1]dashboard_SYAIFUL!$E$4:$BD$76,49,FALSE),0) -> 14 | AN21: =IFERROR(VLOOKUP(E21,[1]dashboard_SYAIFUL!$E$4:$BD$76,50,FALSE),0) -> 21 | AO21: =IFERROR(VLOOKUP('SUMMARY MT 2026'!$E21,[1]dashboard_SYAIFUL!$E$4:$CP$76,89,FALSE),0) -> 11 | AP21: =IFERROR(VLOOKUP('SUMMARY MT 2026'!$E21,[1]dashboard_SYAIFUL!$E$4:$CP$76,90,FALSE),0) -> 24 | AR21: =35-Table2[[#This Row],[PARETO SKU MAR 2026]] -> 35 | AT21: =35-Table2[[#This Row],[PARETO SKU MAR 2026]] -> 35 | AV21: =35-Table2[[#This Row],[PARETO SKU MAR 2026]] -> 35 | AX21: =35-Table2[[#This Row],[PARETO SKU MAR 2026]] -> 35 | AZ21: =35-Table2[[#This Row],[PARETO SKU MAR 2026]] -> 35 | BB21: =35-Table2[[#This Row],[PARETO SKU MAR 2026]] -> 35 | BD21: =35-Table2[[#This Row],[PARETO SKU MAR 2026]] -> 35 | BF21: =35-Table2[[#This Row],[PARETO SKU MAR 2026]] -> 35 | BH21: =35-Table2[[#This Row],[PARETO SKU MAR 2026]] -> 35 | BJ21: =35-Table2[[#This Row],[PARETO SKU MAR 2026]] -> 35
B22: KL-LOVE | C22: =RANK(IFERROR(VLOOKUP(Table2[[#This Row],[CUSTNO_DIST]],STM!B:C,2,FALSE),0),STM!$C$5:$C$65,0) -> 19 | D22: SPM.LOVE MARKET | E22: MTA00101-10100006 | F22: 2.2836572e+08 | G22: 19030476 | H22: =RANK(G22,$G$4:$G$64,0) -> 19 | I22: 15703135 | J22: =RANK(I22,$I$4:$I$64,0) -> 22 | K22: =IFERROR(G22/I22-1," ") -> 0.21189024 | L22: =IFERROR(VLOOKUP(Table2[[#This Row],[CUST-GROUP]],$E$70:$K$88,7,FALSE),0) -> 0.21189024 | M22: =IFERROR(VLOOKUP(E22,STM!G:K,4,FALSE),0)/G22-1 -> 0.049004938 | N22: =IFERROR(VLOOKUP('SUMMARY MT 2026'!$B22,$E$70:$M$88,8,FALSE),0) -> 0.049004938 | O22: =IFERROR(VLOOKUP(E22,STM!G:K,5,FALSE),0)/G22-1 -> -0.21943129 | P22: =IFERROR(VLOOKUP('SUMMARY MT 2026'!$B22,$E$70:$M$88,9,FALSE),0) -> -0.21943129 | AK22: =IFERROR(VLOOKUP(E22,[1]dashboard_SYAIFUL!$E$4:$AZ$76,47,FALSE),0) -> 22 | AL22: =IFERROR(VLOOKUP(E22,[1]dashboard_SYAIFUL!$E$4:$AZ$76,48,FALSE),0) -> 13 | AM22: =IFERROR(VLOOKUP(E22,[1]dashboard_SYAIFUL!$E$4:$BD$76,49,FALSE),0) -> 15 | AN22: =IFERROR(VLOOKUP(E22,[1]dashboard_SYAIFUL!$E$4:$BD$76,50,FALSE),0) -> 20 | AO22: =IFERROR(VLOOKUP('SUMMARY MT 2026'!$E22,[1]dashboard_SYAIFUL!$E$4:$CP$76,89,FALSE),0) -> 12 | AP22: =IFERROR(VLOOKUP('SUMMARY MT 2026'!$E22,[1]dashboard_SYAIFUL!$E$4:$CP$76,90,FALSE),0) -> 23 | AR22: =35-Table2[[#This Row],[PARETO SKU MAR 2026]] -> 35 | AT22: =35-Table2[[#This Row],[PARETO SKU MAR 2026]] -> 35 | AV22: =35-Table2[[#This Row],[PARETO SKU MAR 2026]] -> 35 | AX22: =35-Table2[[#This Row],[PARETO SKU MAR 2026]] -> 35 | AZ22: =35-Table2[[#This Row],[PARETO SKU MAR 2026]] -> 35 | BB22: =35-Table2[[#This Row],[PARETO SKU MAR 2026]] -> 35 | BD22: =35-Table2[[#This Row],[PARETO SKU MAR 2026]] -> 35 | BF22: =35-Table2[[#This Row],[PARETO SKU MAR 2026]] -> 35 | BH22: =35-Table2[[#This Row],[PARETO SKU MAR 2026]] -> 35 | BJ22: =35-Table2[[#This Row],[PARETO SKU MAR 2026]] -> 35
B23: KL-VICTORIA | C23: =RANK(IFERROR(VLOOKUP(Table2[[#This Row],[CUSTNO_DIST]],STM!B:C,2,FALSE),0),STM!$C$5:$C$65,0) -> 43 | D23: MM.VICTORIA TIBAN | E23: MTA00101-10100036 | F23: 2.2168141e+08 | G23: 18473451 | H23: =RANK(G23,$G$4:$G$64,0) -> 20 | I23: 18588468 | J23: =RANK(I23,$I$4:$I$64,0) -> 18 | K23: =IFERROR(G23/I23-1," ") -> -0.0061875181 | L23: =IFERROR(VLOOKUP(Table2[[#This Row],[CUST-GROUP]],$E$70:$K$88,7,FALSE),0) -> 0.14615526 | M23: =IFERROR(VLOOKUP(E23,STM!G:K,4,FALSE),0)/G23-1 -> -0.47936004 | N23: =IFERROR(VLOOKUP('SUMMARY MT 2026'!$B23,$E$70:$M$88,8,FALSE),0) -> -0.070447779 | O23: =IFERROR(VLOOKUP(E23,STM!G:K,5,FALSE),0)/G23-1 -> -1.0004389 | P23: =IFERROR(VLOOKUP('SUMMARY MT 2026'!$B23,$E$70:$M$88,9,FALSE),0) -> -0.62624123 | AK23: =IFERROR(VLOOKUP(E23,[1]dashboard_SYAIFUL!$E$4:$AZ$76,47,FALSE),0) -> 28 | AL23: =IFERROR(VLOOKUP(E23,[1]dashboard_SYAIFUL!$E$4:$AZ$76,48,FALSE),0) -> 7 | AM23: =IFERROR(VLOOKUP(E23,[1]dashboard_SYAIFUL!$E$4:$BD$76,49,FALSE),0) -> 11 | AN23: =IFERROR(VLOOKUP(E23,[1]dashboard_SYAIFUL!$E$4:$BD$76,50,FALSE),0) -> 24 | AO23: =IFERROR(VLOOKUP('SUMMARY MT 2026'!$E23,[1]dashboard_SYAIFUL!$E$4:$CP$76,89,FALSE),0) -> 0 | AP23: =IFERROR(VLOOKUP('SUMMARY MT 2026'!$E23,[1]dashboard_SYAIFUL!$E$4:$CP$76,90,FALSE),0) -> 35 | AR23: =35-Table2[[#This Row],[PARETO SKU MAR 2026]] -> 35 | AT23: =35-Table2[[#This Row],[PARETO SKU MAR 2026]] -> 35 | AV23: =35-Table2[[#This Row],[PARETO SKU MAR 2026]] -> 35 | AX23: =35-Table2[[#This Row],[PARETO SKU MAR 2026]] -> 35 | AZ23: =35-Table2[[#This Row],[PARETO SKU MAR 2026]] -> 35 | BB23: =35-Table2[[#This Row],[PARETO SKU MAR 2026]] -> 35 | BD23: =35-Table2[[#This Row],[PARETO SKU MAR 2026]] -> 35 | BF23: =35-Table2[[#This Row],[PARETO SKU MAR 2026]] -> 35 | BH23: =35-Table2[[#This Row],[PARETO SKU MAR 2026]] -> 35 | BJ23: =35-Table2[[#This Row],[PARETO SKU MAR 2026]] -> 35
B24: KL-STAR | C24: =RANK(IFERROR(VLOOKUP(Table2[[#This Row],[CUSTNO_DIST]],STM!B:C,2,FALSE),0),STM!$C$5:$C$65,0) -> 17 | D24: MM.GALAXY STAR | E24: MTA00101-10100039 | F24: 2.1129283e+08 | G24: 17607736 | H24: =RANK(G24,$G$4:$G$64,0) -> 21 | I24: 16481530 | J24: =RANK(I24,$I$4:$I$64,0) -> 19 | K24: =IFERROR(G24/I24-1," ") -> 0.068331396 | L24: =IFERROR(VLOOKUP(Table2[[#This Row],[CUST-GROUP]],$E$70:$K$88,7,FALSE),0) -> 0.12954458 | M24: =IFERROR(VLOOKUP(E24,STM!G:K,4,FALSE),0)/G24-1 -> -0.077007601 | N24: =IFERROR(VLOOKUP('SUMMARY MT 2026'!$B24,$E$70:$M$88,8,FALSE),0) -> 0.47930017 | O24: =IFERROR(VLOOKUP(E24,STM!G:K,5,FALSE),0)/G24-1 -> 0.23803114 | P24: =IFERROR(VLOOKUP('SUMMARY MT 2026'!$B24,$E$70:$M$88,9,FALSE),0) -> -0.13220472 | AK24: =IFERROR(VLOOKUP(E24,[1]dashboard_SYAIFUL!$E$4:$AZ$76,47,FALSE),0) -> 20 | AL24: =IFERROR(VLOOKUP(E24,[1]dashboard_SYAIFUL!$E$4:$AZ$76,48,FALSE),0) -> 15 | AM24: =IFERROR(VLOOKUP(E24,[1]dashboard_SYAIFUL!$E$4:$BD$76,49,FALSE),0) -> 11 | AN24: =IFERROR(VLOOKUP(E24,[1]dashboard_SYAIFUL!$E$4:$BD$76,50,FALSE),0) -> 24 | AO24: =IFERROR(VLOOKUP('SUMMARY MT 2026'!$E24,[1]dashboard_SYAIFUL!$E$4:$CP$76,89,FALSE),0) -> 6 | AP24: =IFERROR(VLOOKUP('SUMMARY MT 2026'!$E24,[1]dashboard_SYAIFUL!$E$4:$CP$76,90,FALSE),0) -> 29 | AR24: =35-Table2[[#This Row],[PARETO SKU MAR 2026]] -> 35 | AT24: =35-Table2[[#This Row],[PARETO SKU MAR 2026]] -> 35 | AV24: =35-Table2[[#This Row],[PARETO SKU MAR 2026]] -> 35 | AX24: =35-Table2[[#This Row],[PARETO SKU MAR 2026]] -> 35 | AZ24: =35-Table2[[#This Row],[PARETO SKU MAR 2026]] -> 35 | BB24: =35-Table2[[#This Row],[PARETO SKU MAR 2026]] -> 35 | BD24: =35-Table2[[#This Row],[PARETO SKU MAR 2026]] -> 35 | BF24: =35-Table2[[#This Row],[PARETO SKU MAR 2026]] -> 35 | BH24: =35-Table2[[#This Row],[PARETO SKU MAR 2026]] -> 35 | BJ24: =35-Table2[[#This Row],[PARETO SKU MAR 2026]] -> 35
B25: KL-TOP 100 | C25: =RANK(IFERROR(VLOOKUP(Table2[[#This Row],[CUSTNO_DIST]],STM!B:C,2,FALSE),0),STM!$C$5:$C$65,0) -> 16 | D25: PT.TOP SERATUS SEJATI TUNAS | E25: MTA00101-10100027 | F25: 2.0627881e+08 | G25: 17189901 | H25: =RANK(G25,$G$4:$G$64,0) -> 22 | I25: 16074225 | J25: =RANK(I25,$I$4:$I$64,0) -> 20 | K25: =IFERROR(G25/I25-1," ") -> 0.06940773 | L25: =IFERROR(VLOOKUP(Table2[[#This Row],[CUST-GROUP]],$E$70:$K$88,7,FALSE),0) -> 0.20819267 | M25: =IFERROR(VLOOKUP(E25,STM!G:K,4,FALSE),0)/G25-1 -> -0.44700405 | N25: =IFERROR(VLOOKUP('SUMMARY MT 2026'!$B25,$E$70:$M$88,8,FALSE),0) -> 0.23890659 | O25: =IFERROR(VLOOKUP(E25,STM!G:K,5,FALSE),0)/G25-1 -> 0.7581033 | P25: =IFERROR(VLOOKUP('SUMMARY MT 2026'!$B25,$E$70:$M$88,9,FALSE),0) -> -0.339362 | AK25: =IFERROR(VLOOKUP(E25,[1]dashboard_SYAIFUL!$E$4:$AZ$76,47,FALSE),0) -> 20 | AL25: =IFERROR(VLOOKUP(E25,[1]dashboard_SYAIFUL!$E$4:$AZ$76,48,FALSE),0) -> 15 | AM25: =IFERROR(VLOOKUP(E25,[1]dashboard_SYAIFUL!$E$4:$BD$76,49,FALSE),0) -> 12 | AN25: =IFERROR(VLOOKUP(E25,[1]dashboard_SYAIFUL!$E$4:$BD$76,50,FALSE),0) -> 23 | AO25: =IFERROR(VLOOKUP('SUMMARY MT 2026'!$E25,[1]dashboard_SYAIFUL!$E$4:$CP$76,89,FALSE),0) -> 10 | AP25: =IFERROR(VLOOKUP('SUMMARY MT 2026'!$E25,[1]dashboard_SYAIFUL!$E$4:$CP$76,90,FALSE),0) -> 25 | AR25: =35-Table2[[#This Row],[PARETO SKU MAR 2026]] -> 35 | AT25: =35-Table2[[#This Row],[PARETO SKU MAR 2026]] -> 35 | AV25: =35-Table2[[#This Row],[PARETO SKU MAR 2026]] -> 35 | AX25: =35-Table2[[#This Row],[PARETO SKU MAR 2026]] -> 35 | AZ25: =35-Table2[[#This Row],[PARETO SKU MAR 2026]] -> 35 | BB25: =35-Table2[[#This Row],[PARETO SKU MAR 2026]] -> 35 | BD25: =35-Table2[[#This Row],[PARETO SKU MAR 2026]] -> 35 | BF25: =35-Table2[[#This Row],[PARETO SKU MAR 2026]] -> 35 | BH25: =35-Table2[[#This Row],[PARETO SKU MAR 2026]] -> 35 | BJ25: =35-Table2[[#This Row],[PARETO SKU MAR 2026]] -> 35
B26: KL-STAR | C26: =RANK(IFERROR(VLOOKUP(Table2[[#This Row],[CUSTNO_DIST]],STM!B:C,2,FALSE),0),STM!$C$5:$C$65,0) -> 10 | D26: MM.GLOBAL STAR LEGENDA | E26: MTA00101-10100004 | F26: 2.0067736e+08 | G26: 16723114 | H26: =RANK(G26,$G$4:$G$64,0) -> 23 | I26: 9259149.4 | J26: =RANK(I26,$I$4:$I$64,0) -> 32 | K26: =IFERROR(G26/I26-1," ") -> 0.80611771 | L26: =IFERROR(VLOOKUP(Table2[[#This Row],[CUST-GROUP]],$E$70:$K$88,7,FALSE),0) -> 0.12954458 | M26: =IFERROR(VLOOKUP(E26,STM!G:K,4,FALSE),0)/G26-1 -> 0.80003387 | N26: =IFERROR(VLOOKUP('SUMMARY MT 2026'!$B26,$E$70:$M$88,8,FALSE),0) -> 0.47930017 | O26: =IFERROR(VLOOKUP(E26,STM!G:K,5,FALSE),0)/G26-1 -> 0.75859544 | P26: =IFERROR(VLOOKUP('SUMMARY MT 2026'!$B26,$E$70:$M$88,9,FALSE),0) -> -0.13220472 | AK26: =IFERROR(VLOOKUP(E26,[1]dashboard_SYAIFUL!$E$4:$AZ$76,47,FALSE),0) -> 13 | AL26: =IFERROR(VLOOKUP(E26,[1]dashboard_SYAIFUL!$E$4:$AZ$76,48,FALSE),0) -> 22 | AM26: =IFERROR(VLOOKUP(E26,[1]dashboard_SYAIFUL!$E$4:$BD$76,49,FALSE),0) -> 12 | AN26: =IFERROR(VLOOKUP(E26,[1]dashboard_SYAIFUL!$E$4:$BD$76,50,FALSE),0) -> 23 | AO26: =IFERROR(VLOOKUP('SUMMARY MT 2026'!$E26,[1]dashboard_SYAIFUL!$E$4:$CP$76,89,FALSE),0) -> 9 | AP26: =IFERROR(VLOOKUP('SUMMARY MT 2026'!$E26,[1]dashboard_SYAIFUL!$E$4:$CP$76,90,FALSE),0) -> 26 | AR26: =35-Table2[[#This Row],[PARETO SKU MAR 2026]] -> 35 | AT26: =35-Table2[[#This Row],[PARETO SKU MAR 2026]] -> 35 | AV26: =35-Table2[[#This Row],[PARETO SKU MAR 2026]] -> 35 | AX26: =35-Table2[[#This Row],[PARETO SKU MAR 2026]] -> 35 | AZ26: =35-Table2[[#This Row],[PARETO SKU MAR 2026]] -> 35 | BB26: =35-Table2[[#This Row],[PARETO SKU MAR 2026]] -> 35 | BD26: =35-Table2[[#This Row],[PARETO SKU MAR 2026]] -> 35 | BF26: =35-Table2[[#This Row],[PARETO SKU MAR 2026]] -> 35 | BH26: =35-Table2[[#This Row],[PARETO SKU MAR 2026]] -> 35 | BJ26: =35-Table2[[#This Row],[PARETO SKU MAR 2026]] -> 35
... B55: KL-INDAH | C55: =RANK(IFERROR(VLOOKUP(Table2[[#This Row],[CUSTNO_DIST]],STM!B:C,2,FALSE),0),STM!$C$5:$C$65,0) -> 59 | D55: PT.ROYAL SUPERMARKET - PASIR PUTIH | E55: MTA00101-10100059 | F55: 45135040 | G55: 3761253.3 | H55: =RANK(G55,$G$4:$G$64,0) -> 52 | I55: 1745607.6 | J55: =RANK(I55,$I$4:$I$64,0) -> 54 | K55: =IFERROR(G55/I55-1," ") -> 1.1546957 | L55: =IFERROR(VLOOKUP(Table2[[#This Row],[CUST-GROUP]],$E$70:$K$88,7,FALSE),0) -> 0.03542864 | M55: =IFERROR(VLOOKUP(E55,STM!G:K,4,FALSE),0)/G55-1 -> -0.83487393 | N55: =IFERROR(VLOOKUP('SUMMARY MT 2026'!$B55,$E$70:$M$88,8,FALSE),0) -> -0.15994414 | O55: =IFERROR(VLOOKUP(E55,STM!G:K,5,FALSE),0)/G55-1 -> -1 | P55: =IFERROR(VLOOKUP('SUMMARY MT 2026'!$B55,$E$70:$M$88,9,FALSE),0) -> -0.14096078 | AK55: =IFERROR(VLOOKUP(E55,[1]dashboard_SYAIFUL!$E$4:$AZ$76,47,FALSE),0) -> 14 | AL55: =IFERROR(VLOOKUP(E55,[1]dashboard_SYAIFUL!$E$4:$AZ$76,48,FALSE),0) -> 21 | AM55: =IFERROR(VLOOKUP(E55,[1]dashboard_SYAIFUL!$E$4:$BD$76,49,FALSE),0) -> 1 | AN55: =IFERROR(VLOOKUP(E55,[1]dashboard_SYAIFUL!$E$4:$BD$76,50,FALSE),0) -> 34 | AO55: =IFERROR(VLOOKUP('SUMMARY MT 2026'!$E55,[1]dashboard_SYAIFUL!$E$4:$CP$76,89,FALSE),0) -> 0 | AP55: =IFERROR(VLOOKUP('SUMMARY MT 2026'!$E55,[1]dashboard_SYAIFUL!$E$4:$CP$76,90,FALSE),0) -> 35 | AR55: =35-Table2[[#This Row],[PARETO SKU MAR 2026]] -> 35 | AT55: =35-Table2[[#This Row],[PARETO SKU MAR 2026]] -> 35 | AV55: =35-Table2[[#This Row],[PARETO SKU MAR 2026]] -> 35 | AX55: =35-Table2[[#This Row],[PARETO SKU MAR 2026]] -> 35 | AZ55: =35-Table2[[#This Row],[PARETO SKU MAR 2026]] -> 35 | BB55: =35-Table2[[#This Row],[PARETO SKU MAR 2026]] -> 35 | BD55: =35-Table2[[#This Row],[PARETO SKU MAR 2026]] -> 35 | BF55: =35-Table2[[#This Row],[PARETO SKU MAR 2026]] -> 35 | BH55: =35-Table2[[#This Row],[PARETO SKU MAR 2026]] -> 35 | BJ55: =35-Table2[[#This Row],[PARETO SKU MAR 2026]] -> 35
B56: KL-GOGO | C56: =RANK(IFERROR(VLOOKUP(Table2[[#This Row],[CUSTNO_DIST]],STM!B:C,2,FALSE),0),STM!$C$5:$C$65,0) -> 25 | D56: SUPERMARKET GOGO K-SQUARE | E56: MTA00101-10100066 | F56: 42449178 | G56: 3537431.5 | H56: =RANK(G56,$G$4:$G$64,0) -> 53 | I56: 0 | J56: =RANK(I56,$I$4:$I$64,0) -> 58 | K56: =IFERROR(G56/I56-1,1) -> 1 | L56: =IFERROR(VLOOKUP(Table2[[#This Row],[CUST-GROUP]],$E$70:$K$88,7,FALSE),0) -> 0.31105347 | M56: =IFERROR(VLOOKUP(E56,STM!G:K,4,FALSE),0)/G56-1 -> 1.4923911 | N56: =IFERROR(VLOOKUP('SUMMARY MT 2026'!$B56,$E$70:$M$88,8,FALSE),0) -> -0.202461 | O56: =IFERROR(VLOOKUP(E56,STM!G:K,5,FALSE),0)/G56-1 -> 3.119164 | P56: =IFERROR(VLOOKUP('SUMMARY MT 2026'!$B56,$E$70:$M$88,9,FALSE),0) -> -0.48667136 | AK56: =IFERROR(VLOOKUP(E56,[1]dashboard_SYAIFUL!$E$4:$AZ$76,47,FALSE),0) -> 21 | AL56: =IFERROR(VLOOKUP(E56,[1]dashboard_SYAIFUL!$E$4:$AZ$76,48,FALSE),0) -> 14 | AM56: =IFERROR(VLOOKUP(E56,[1]dashboard_SYAIFUL!$E$4:$BD$76,49,FALSE),0) -> 13 | AN56: =IFERROR(VLOOKUP(E56,[1]dashboard_SYAIFUL!$E$4:$BD$76,50,FALSE),0) -> 22 | AO56: =IFERROR(VLOOKUP('SUMMARY MT 2026'!$E56,[1]dashboard_SYAIFUL!$E$4:$CP$76,89,FALSE),0) -> 17 | AP56: =IFERROR(VLOOKUP('SUMMARY MT 2026'!$E56,[1]dashboard_SYAIFUL!$E$4:$CP$76,90,FALSE),0) -> 18 | AR56: =35-Table2[[#This Row],[PARETO SKU MAR 2026]] -> 35 | AT56: =35-Table2[[#This Row],[PARETO SKU MAR 2026]] -> 35 | AV56: =35-Table2[[#This Row],[PARETO SKU MAR 2026]] -> 35 | AX56: =35-Table2[[#This Row],[PARETO SKU MAR 2026]] -> 35 | AZ56: =35-Table2[[#This Row],[PARETO SKU MAR 2026]] -> 35 | BB56: =35-Table2[[#This Row],[PARETO SKU MAR 2026]] -> 35 | BD56: =35-Table2[[#This Row],[PARETO SKU MAR 2026]] -> 35 | BF56: =35-Table2[[#This Row],[PARETO SKU MAR 2026]] -> 35 | BH56: =35-Table2[[#This Row],[PARETO SKU MAR 2026]] -> 35 | BJ56: =35-Table2[[#This Row],[PARETO SKU MAR 2026]] -> 35
B57: KL- | C57: =RANK(IFERROR(VLOOKUP(Table2[[#This Row],[CUSTNO_DIST]],STM!B:C,2,FALSE),0),STM!$C$5:$C$65,0) -> 54 | D57: PT.ZERO TOTAL | E57: MTA00101-10100024 | F57: 29163422 | G57: 2430285.2 | H57: =RANK(G57,$G$4:$G$64,0) -> 54 | I57: 2622409.4 | J57: =RANK(I57,$I$4:$I$64,0) -> 52 | K57: =IFERROR(G57/I57-1," ") -> -0.073262484 | L57: =IFERROR(VLOOKUP(Table2[[#This Row],[CUST-GROUP]],$E$70:$K$88,7,FALSE),0) -> -0.10593556 | M57: =IFERROR(VLOOKUP(E57,STM!G:K,4,FALSE),0)/G57-1 -> -0.11488529 | N57: =IFERROR(VLOOKUP('SUMMARY MT 2026'!$B57,$E$70:$M$88,8,FALSE),0) -> 0.48461474 | O57: =IFERROR(VLOOKUP(E57,STM!G:K,5,FALSE),0)/G57-1 -> -0.51935328 | P57: =IFERROR(VLOOKUP('SUMMARY MT 2026'!$B57,$E$70:$M$88,9,FALSE),0) -> -0.12003958 | AK57: =IFERROR(VLOOKUP(E57,[1]dashboard_SYAIFUL!$E$4:$AZ$76,47,FALSE),0) -> 11 | AL57: =IFERROR(VLOOKUP(E57,[1]dashboard_SYAIFUL!$E$4:$AZ$76,48,FALSE),0) -> 24 | AM57: =IFERROR(VLOOKUP(E57,[1]dashboard_SYAIFUL!$E$4:$BD$76,49,FALSE),0) -> 5 | AN57: =IFERROR(VLOOKUP(E57,[1]dashboard_SYAIFUL!$E$4:$BD$76,50,FALSE),0) -> 30 | AO57: =IFERROR(VLOOKUP('SUMMARY MT 2026'!$E57,[1]dashboard_SYAIFUL!$E$4:$CP$76,89,FALSE),0) -> 6 | AP57: =IFERROR(VLOOKUP('SUMMARY MT 2026'!$E57,[1]dashboard_SYAIFUL!$E$4:$CP$76,90,FALSE),0) -> 29 | AR57: =35-Table2[[#This Row],[PARETO SKU MAR 2026]] -> 35 | AT57: =35-Table2[[#This Row],[PARETO SKU MAR 2026]] -> 35 | AV57: =35-Table2[[#This Row],[PARETO SKU MAR 2026]] -> 35 | AX57: =35-Table2[[#This Row],[PARETO SKU MAR 2026]] -> 35 | AZ57: =35-Table2[[#This Row],[PARETO SKU MAR 2026]] -> 35 | BB57: =35-Table2[[#This Row],[PARETO SKU MAR 2026]] -> 35 | BD57: =35-Table2[[#This Row],[PARETO SKU MAR 2026]] -> 35 | BF57: =35-Table2[[#This Row],[PARETO SKU MAR 2026]] -> 35 | BH57: =35-Table2[[#This Row],[PARETO SKU MAR 2026]] -> 35 | BJ57: =35-Table2[[#This Row],[PARETO SKU MAR 2026]] -> 35
B58: KL- | C58: =RANK(IFERROR(VLOOKUP(Table2[[#This Row],[CUSTNO_DIST]],STM!B:C,2,FALSE),0),STM!$C$5:$C$65,0) -> 56 | D58: MM.OHS MART | E58: MTA00101-10100056 | F58: 27185267 | G58: 2265438.9 | H58: =RANK(G58,$G$4:$G$64,0) -> 55 | I58: 0 | J58: =RANK(I58,$I$4:$I$64,0) -> 58 | K58: =IFERROR(G58/I58-1,1) -> 1 | L58: =IFERROR(VLOOKUP(Table2[[#This Row],[CUST-GROUP]],$E$70:$K$88,7,FALSE),0) -> -0.10593556 | M58: =IFERROR(VLOOKUP(E58,STM!G:K,4,FALSE),0)/G58-1 -> -0.13697258 | N58: =IFERROR(VLOOKUP('SUMMARY MT 2026'!$B58,$E$70:$M$88,8,FALSE),0) -> 0.48461474 | O58: =IFERROR(VLOOKUP(E58,STM!G:K,5,FALSE),0)/G58-1 -> -1 | P58: =IFERROR(VLOOKUP('SUMMARY MT 2026'!$B58,$E$70:$M$88,9,FALSE),0) -> -0.12003958 | AK58: =IFERROR(VLOOKUP(E58,[1]dashboard_SYAIFUL!$E$4:$AZ$76,47,FALSE),0) -> 15 | AL58: =IFERROR(VLOOKUP(E58,[1]dashboard_SYAIFUL!$E$4:$AZ$76,48,FALSE),0) -> 20 | AM58: =IFERROR(VLOOKUP(E58,[1]dashboard_SYAIFUL!$E$4:$BD$76,49,FALSE),0) -> 6 | AN58: =IFERROR(VLOOKUP(E58,[1]dashboard_SYAIFUL!$E$4:$BD$76,50,FALSE),0) -> 29 | AO58: =IFERROR(VLOOKUP('SUMMARY MT 2026'!$E58,[1]dashboard_SYAIFUL!$E$4:$CP$76,89,FALSE),0) -> 0 | AP58: =IFERROR(VLOOKUP('SUMMARY MT 2026'!$E58,[1]dashboard_SYAIFUL!$E$4:$CP$76,90,FALSE),0) -> 35 | AR58: =35-Table2[[#This Row],[PARETO SKU MAR 2026]] -> 35 | AT58: =35-Table2[[#This Row],[PARETO SKU MAR 2026]] -> 35 | AV58: =35-Table2[[#This Row],[PARETO SKU MAR 2026]] -> 35 | AX58: =35-Table2[[#This Row],[PARETO SKU MAR 2026]] -> 35 | AZ58: =35-Table2[[#This Row],[PARETO SKU MAR 2026]] -> 35 | BB58: =35-Table2[[#This Row],[PARETO SKU MAR 2026]] -> 35 | BD58: =35-Table2[[#This Row],[PARETO SKU MAR 2026]] -> 35 | BF58: =35-Table2[[#This Row],[PARETO SKU MAR 2026]] -> 35 | BH58: =35-Table2[[#This Row],[PARETO SKU MAR 2026]] -> 35 | BJ58: =35-Table2[[#This Row],[PARETO SKU MAR 2026]] -> 35
B59: KL-STAR | C59: =RANK(IFERROR(VLOOKUP(Table2[[#This Row],[CUSTNO_DIST]],STM!B:C,2,FALSE),0),STM!$C$5:$C$65,0) -> 57 | D59: MM.BPS BALOI BLOK 2 | E59: MTA00101-10100052 | F59: 20642250 | G59: 1720187.5 | H59: =RANK(G59,$G$4:$G$64,0) -> 56 | I59: 969699.56 | J59: =RANK(I59,$I$4:$I$64,0) -> 57 | K59: =IFERROR(G59/I59-1," ") -> 0.7739386 | L59: =IFERROR(VLOOKUP(Table2[[#This Row],[CUST-GROUP]],$E$70:$K$88,7,FALSE),0) -> 0.12954458 | M59: =IFERROR(VLOOKUP(E59,STM!G:K,4,FALSE),0)/G59-1 -> 0.058967287 | N59: =IFERROR(VLOOKUP('SUMMARY MT 2026'!$B59,$E$70:$M$88,8,FALSE),0) -> 0.47930017 | O59: =IFERROR(VLOOKUP(E59,STM!G:K,5,FALSE),0)/G59-1 -> -1 | P59: =IFERROR(VLOOKUP('SUMMARY MT 2026'!$B59,$E$70:$M$88,9,FALSE),0) -> -0.13220472 | AK59: =IFERROR(VLOOKUP(E59,[1]dashboard_SYAIFUL!$E$4:$AZ$76,47,FALSE),0) -> 10 | AL59: =IFERROR(VLOOKUP(E59,[1]dashboard_SYAIFUL!$E$4:$AZ$76,48,FALSE),0) -> 25 | AM59: =IFERROR(VLOOKUP(E59,[1]dashboard_SYAIFUL!$E$4:$BD$76,49,FALSE),0) -> 4 | AN59: =IFERROR(VLOOKUP(E59,[1]dashboard_SYAIFUL!$E$4:$BD$76,50,FALSE),0) -> 31 | AO59: =IFERROR(VLOOKUP('SUMMARY MT 2026'!$E59,[1]dashboard_SYAIFUL!$E$4:$CP$76,89,FALSE),0) -> 0 | AP59: =IFERROR(VLOOKUP('SUMMARY MT 2026'!$E59,[1]dashboard_SYAIFUL!$E$4:$CP$76,90,FALSE),0) -> 35 | AR59: =35-Table2[[#This Row],[PARETO SKU MAR 2026]] -> 35 | AT59: =35-Table2[[#This Row],[PARETO SKU MAR 2026]] -> 35 | AV59: =35-Table2[[#This Row],[PARETO SKU MAR 2026]] -> 35 | AX59: =35-Table2[[#This Row],[PARETO SKU MAR 2026]] -> 35 | AZ59: =35-Table2[[#This Row],[PARETO SKU MAR 2026]] -> 35 | BB59: =35-Table2[[#This Row],[PARETO SKU MAR 2026]] -> 35 | BD59: =35-Table2[[#This Row],[PARETO SKU MAR 2026]] -> 35 | BF59: =35-Table2[[#This Row],[PARETO SKU MAR 2026]] -> 35 | BH59: =35-Table2[[#This Row],[PARETO SKU MAR 2026]] -> 35 | BJ59: =35-Table2[[#This Row],[PARETO SKU MAR 2026]] -> 35
B60: KL-YOSS | C60: =RANK(IFERROR(VLOOKUP(Table2[[#This Row],[CUSTNO_DIST]],STM!B:C,2,FALSE),0),STM!$C$5:$C$65,0) -> 53 | D60: MM.YOSS MART | E60: MTA00101-10100055 | F60: 18842160 | G60: 1570180 | H60: =RANK(G60,$G$4:$G$64,0) -> 57 | I60: 1059699.5 | J60: =RANK(I60,$I$4:$I$64,0) -> 56 | K60: =IFERROR(G60/I60-1," ") -> 0.48172195 | L60: =IFERROR(VLOOKUP(Table2[[#This Row],[CUST-GROUP]],$E$70:$K$88,7,FALSE),0) -> 0.48172195 | M60: =IFERROR(VLOOKUP(E60,STM!G:K,4,FALSE),0)/G60-1 -> 0.036548317 | N60: =IFERROR(VLOOKUP('SUMMARY MT 2026'!$B60,$E$70:$M$88,8,FALSE),0) -> 0.036548317 | O60: =IFERROR(VLOOKUP(E60,STM!G:K,5,FALSE),0)/G60-1 -> 0.23334595 | P60: =IFERROR(VLOOKUP('SUMMARY MT 2026'!$B60,$E$70:$M$88,9,FALSE),0) -> 0.23334595 | AK60: =IFERROR(VLOOKUP(E60,[1]dashboard_SYAIFUL!$E$4:$AZ$76,47,FALSE),0) -> 11 | AL60: =IFERROR(VLOOKUP(E60,[1]dashboard_SYAIFUL!$E$4:$AZ$76,48,FALSE),0) -> 24 | AM60: =IFERROR(VLOOKUP(E60,[1]dashboard_SYAIFUL!$E$4:$BD$76,49,FALSE),0) -> 7 | AN60: =IFERROR(VLOOKUP(E60,[1]dashboard_SYAIFUL!$E$4:$BD$76,50,FALSE),0) -> 28 | AO60: =IFERROR(VLOOKUP('SUMMARY MT 2026'!$E60,[1]dashboard_SYAIFUL!$E$4:$CP$76,89,FALSE),0) -> 8 | AP60: =IFERROR(VLOOKUP('SUMMARY MT 2026'!$E60,[1]dashboard_SYAIFUL!$E$4:$CP$76,90,FALSE),0) -> 27 | AR60: =35-Table2[[#This Row],[PARETO SKU MAR 2026]] -> 35 | AT60: =35-Table2[[#This Row],[PARETO SKU MAR 2026]] -> 35 | AV60: =35-Table2[[#This Row],[PARETO SKU MAR 2026]] -> 35 | AX60: =35-Table2[[#This Row],[PARETO SKU MAR 2026]] -> 35 | AZ60: =35-Table2[[#This Row],[PARETO SKU MAR 2026]] -> 35 | BB60: =35-Table2[[#This Row],[PARETO SKU MAR 2026]] -> 35 | BD60: =35-Table2[[#This Row],[PARETO SKU MAR 2026]] -> 35 | BF60: =35-Table2[[#This Row],[PARETO SKU MAR 2026]] -> 35 | BH60: =35-Table2[[#This Row],[PARETO SKU MAR 2026]] -> 35 | BJ60: =35-Table2[[#This Row],[PARETO SKU MAR 2026]] -> 35
B61: KA-RAMAYANA | C61: =RANK(IFERROR(VLOOKUP(Table2[[#This Row],[CUSTNO_DIST]],STM!B:C,2,FALSE),0),STM!$C$5:$C$65,0) -> 60 | D61: PT.RAMAYANA LESTARI SENTOSA. TBK | E61: MTA00101-10100008 | F61: 13692434 | G61: 1141036.2 | H61: =RANK(G61,$G$4:$G$64,0) -> 58 | I61: 1755487.3 | J61: =RANK(I61,$I$4:$I$64,0) -> 53 | K61: =IFERROR(G61/I61-1," ") -> -0.35001742 | L61: =IFERROR(VLOOKUP(Table2[[#This Row],[CUST-GROUP]],$E$70:$K$88,7,FALSE),0) -> -0.35001742 | M61: =IFERROR(VLOOKUP(E61,STM!G:K,4,FALSE),0)/G61-1 -> -1 | N61: =IFERROR(VLOOKUP('SUMMARY MT 2026'!$B61,$E$70:$M$88,8,FALSE),0) -> -1 | O61: =IFERROR(VLOOKUP(E61,STM!G:K,5,FALSE),0)/G61-1 -> -1 | P61: =IFERROR(VLOOKUP('SUMMARY MT 2026'!$B61,$E$70:$M$88,9,FALSE),0) -> -1 | AK61: =IFERROR(VLOOKUP(E61,[1]dashboard_SYAIFUL!$E$4:$AZ$76,47,FALSE),0) -> 0 | AL61: =IFERROR(VLOOKUP(E61,[1]dashboard_SYAIFUL!$E$4:$AZ$76,48,FALSE),0) -> 0 | AM61: =IFERROR(VLOOKUP(E61,[1]dashboard_SYAIFUL!$E$4:$BD$76,49,FALSE),0) -> 0 | AN61: =IFERROR(VLOOKUP(E61,[1]dashboard_SYAIFUL!$E$4:$BD$76,50,FALSE),0) -> 0 | AO61: =IFERROR(VLOOKUP('SUMMARY MT 2026'!$E61,[1]dashboard_SYAIFUL!$E$4:$CP$76,89,FALSE),0) -> 0 | AP61: =IFERROR(VLOOKUP('SUMMARY MT 2026'!$E61,[1]dashboard_SYAIFUL!$E$4:$CP$76,90,FALSE),0) -> 0 | AR61: =35-Table2[[#This Row],[PARETO SKU MAR 2026]] -> 35 | AT61: =35-Table2[[#This Row],[PARETO SKU MAR 2026]] -> 35 | AV61: =35-Table2[[#This Row],[PARETO SKU MAR 2026]] -> 35 | AX61: =35-Table2[[#This Row],[PARETO SKU MAR 2026]] -> 35 | AZ61: =35-Table2[[#This Row],[PARETO SKU MAR 2026]] -> 35 | BB61: =35-Table2[[#This Row],[PARETO SKU MAR 2026]] -> 35 | BD61: =35-Table2[[#This Row],[PARETO SKU MAR 2026]] -> 35 | BF61: =35-Table2[[#This Row],[PARETO SKU MAR 2026]] -> 35 | BH61: =35-Table2[[#This Row],[PARETO SKU MAR 2026]] -> 35 | BJ61: =35-Table2[[#This Row],[PARETO SKU MAR 2026]] -> 35
